3f0b0fe93207387ec64f6e0d73155ff05a188efb|ERROR|2022-08-10 10:51:26,355|Socket returns unknown error.
|ERROR|2022-08-10 10:52:00,575|Socket returns unknown error.
|ERROR|2022-08-10 10:52:56,178|Socket returns unknown error.
|ERROR|2022-08-10 10:59:08,165|Call of get_tick_data raised an error:
|ERROR|2022-08-10 10:59:08,166|<class 'requests.exceptions.ConnectionError'>
|ERROR|2022-08-10 10:59:08,166|('Connection aborted.', ConnectionResetError(10054, 'An existing connection was forcibly closed by the remote host', None, 10054, None))
|ERROR|2022-08-22 22:04:26,781|packet queue is empty, aborting
|ERROR|2022-08-22 22:07:49,827|Socket returns unknown error.
|ERROR|2022-08-22 22:11:27,518|Socket returns unknown error.
|ERROR|2022-08-22 22:20:43,428|Connection error: HTTPSConnectionPool(host='api-demo.fxcm.com', port=443): Read timed out. (read timeout=5)
|ERROR|2022-08-22 22:20:43,429|Socket returns unknown error.
|ERROR|2022-08-22 22:27:14,771|Connection error: HTTPSConnectionPool(host='api-demo.fxcm.com', port=443): Max retries exceeded with url: /socket.io/?access_token=97d9d09d13219a0032426fdcf1fe18e656f91a05&agent=pythonquants&wait_for_connection=False&transport=polling&EIO=4&t=1661187434.6226182 (Caused by NewConnectionError('<urllib3.connection.HTTPSConnection object at 0x0000025CE11F4C40>: Failed to establish a new connection: [Errno 11001] getaddrinfo failed'))
|ERROR|2022-08-22 22:27:23,047|Socket returns unknown error.
|ERROR|2022-08-22 22:28:41,821|Error in get_candles: Illegal param. number: 100000
|ERROR|2022-08-22 22:31:01,580|Call of get_tick_data raised an error:
|ERROR|2022-08-22 22:31:01,580|<class 'AttributeError'>
|ERROR|2022-08-22 22:31:01,580|'DataFrame' object has no attribute 'concat'
|ERROR|2022-08-22 22:31:02,513|Call of get_tick_data raised an error:
|ERROR|2022-08-22 22:31:02,513|<class 'AttributeError'>
|ERROR|2022-08-22 22:31:02,513|'DataFrame' object has no attribute 'concat'
|ERROR|2022-08-22 22:31:04,691|Call of get_tick_data raised an error:
|ERROR|2022-08-22 22:31:04,691|<class 'AttributeError'>
|ERROR|2022-08-22 22:31:04,691|'DataFrame' object has no attribute 'concat'
|ERROR|2022-08-22 22:31:04,709|Call of get_tick_data raised an error:
|ERROR|2022-08-22 22:31:04,710|<class 'AttributeError'>
|ERROR|2022-08-22 22:31:04,710|'DataFrame' object has no attribute 'concat'
|ERROR|2022-08-22 22:31:04,733|Call of get_tick_data raised an error:
|ERROR|2022-08-22 22:31:04,733|<class 'AttributeError'>
|ERROR|2022-08-22 22:31:04,734|'DataFrame' object has no attribute 'concat'
|ERROR|2022-08-22 22:31:07,428|Call of get_tick_data raised an error:
|ERROR|2022-08-22 22:31:07,428|<class 'AttributeError'>
|ERROR|2022-08-22 22:31:07,428|'DataFrame' object has no attribute 'concat'
|ERROR|2022-08-22 22:31:07,456|Call of get_tick_data raised an error:
|ERROR|2022-08-22 22:31:07,456|<class 'AttributeError'>
|ERROR|2022-08-22 22:31:07,456|'DataFrame' object has no attribute 'concat'
|ERROR|2022-08-22 22:31:10,281|Call of get_tick_data raised an error:
|ERROR|2022-08-22 22:31:10,281|<class 'AttributeError'>
|ERROR|2022-08-22 22:31:10,281|'DataFrame' object has no attribute 'concat'
|ERROR|2022-08-22 22:31:10,298|Call of get_tick_data raised an error:
|ERROR|2022-08-22 22:31:10,298|<class 'AttributeError'>
|ERROR|2022-08-22 22:31:10,298|'DataFrame' object has no attribute 'concat'
|ERROR|2022-08-22 22:31:13,555|Call of get_tick_data raised an error:
|ERROR|2022-08-22 22:31:13,556|<class 'AttributeError'>
|ERROR|2022-08-22 22:31:13,556|'DataFrame' object has no attribute 'concat'
|ERROR|2022-08-22 22:31:13,881|Call of get_tick_data raised an error:
|ERROR|2022-08-22 22:31:13,881|<class 'AttributeError'>
|ERROR|2022-08-22 22:31:13,881|'DataFrame' object has no attribute 'concat'
|ERROR|2022-08-22 22:31:13,910|Call of get_tick_data raised an error:
|ERROR|2022-08-22 22:31:13,910|<class 'AttributeError'>
|ERROR|2022-08-22 22:31:13,910|'DataFrame' object has no attribute 'concat'
|ERROR|2022-08-22 22:31:16,334|Call of get_tick_data raised an error:
|ERROR|2022-08-22 22:31:16,334|<class 'AttributeError'>
|ERROR|2022-08-22 22:31:16,335|'DataFrame' object has no attribute 'concat'
|ERROR|2022-08-22 22:31:16,349|Call of get_tick_data raised an error:
|ERROR|2022-08-22 22:31:16,349|<class 'AttributeError'>
|ERROR|2022-08-22 22:31:16,349|'DataFrame' object has no attribute 'concat'
|ERROR|2022-08-22 22:31:16,365|Call of get_tick_data raised an error:
|ERROR|2022-08-22 22:31:16,365|<class 'AttributeError'>
|ERROR|2022-08-22 22:31:16,365|'DataFrame' object has no attribute 'concat'
|ERROR|2022-08-22 22:31:16,384|Call of get_tick_data raised an error:
|ERROR|2022-08-22 22:31:16,384|<class 'AttributeError'>
|ERROR|2022-08-22 22:31:16,384|'DataFrame' object has no attribute 'concat'
|ERROR|2022-08-22 22:31:18,290|Call of get_tick_data raised an error:
|ERROR|2022-08-22 22:31:18,290|<class 'AttributeError'>
|ERROR|2022-08-22 22:31:18,290|'DataFrame' object has no attribute 'concat'
|ERROR|2022-08-22 22:31:19,413|Call of get_tick_data raised an error:
|ERROR|2022-08-22 22:31:19,414|<class 'AttributeError'>
|ERROR|2022-08-22 22:31:19,414|'DataFrame' object has no attribute 'concat'
|ERROR|2022-08-22 22:31:20,334|Call of get_tick_data raised an error:
|ERROR|2022-08-22 22:31:20,334|<class 'AttributeError'>
|ERROR|2022-08-22 22:31:20,335|'DataFrame' object has no attribute 'concat'
|ERROR|2022-08-22 22:31:21,008|Call of get_tick_data raised an error:
|ERROR|2022-08-22 22:31:21,009|<class 'AttributeError'>
|ERROR|2022-08-22 22:31:21,009|'DataFrame' object has no attribute 'concat'
|ERROR|2022-08-22 22:31:22,031|Call of get_tick_data raised an error:
|ERROR|2022-08-22 22:31:22,031|<class 'AttributeError'>
|ERROR|2022-08-22 22:31:22,031|'DataFrame' object has no attribute 'concat'
|ERROR|2022-08-22 22:31:23,007|Call of get_tick_data raised an error:
|ERROR|2022-08-22 22:31:23,007|<class 'AttributeError'>
|ERROR|2022-08-22 22:31:23,007|'DataFrame' object has no attribute 'concat'
|ERROR|2022-08-22 22:31:23,815|Call of get_tick_data raised an error:
|ERROR|2022-08-22 22:31:23,815|<class 'AttributeError'>
|ERROR|2022-08-22 22:31:23,816|'DataFrame' object has no attribute 'concat'
|ERROR|2022-08-22 22:31:23,827|Call of get_tick_data raised an error:
|ERROR|2022-08-22 22:31:23,827|<class 'AttributeError'>
|ERROR|2022-08-22 22:31:23,827|'DataFrame' object has no attribute 'concat'
|ERROR|2022-08-22 22:31:24,423|Call of get_tick_data raised an error:
|ERROR|2022-08-22 22:31:24,424|<class 'AttributeError'>
|ERROR|2022-08-22 22:31:24,424|'DataFrame' object has no attribute 'concat'
|ERROR|2022-08-22 22:31:25,246|Call of get_tick_data raised an error:
|ERROR|2022-08-22 22:31:25,247|<class 'AttributeError'>
|ERROR|2022-08-22 22:31:25,247|'DataFrame' object has no attribute 'concat'
|ERROR|2022-08-22 22:31:28,316|Call of get_tick_data raised an error:
|ERROR|2022-08-22 22:31:28,316|<class 'AttributeError'>
|ERROR|2022-08-22 22:31:28,316|'DataFrame' object has no attribute 'concat'
|ERROR|2022-08-22 22:31:28,829|Call of get_tick_data raised an error:
|ERROR|2022-08-22 22:31:28,830|<class 'AttributeError'>
|ERROR|2022-08-22 22:31:28,830|'DataFrame' object has no attribute 'concat'
|ERROR|2022-08-22 22:31:30,467|Call of get_tick_data raised an error:
|ERROR|2022-08-22 22:31:30,468|<class 'AttributeError'>
|ERROR|2022-08-22 22:31:30,468|'DataFrame' object has no attribute 'concat'
|ERROR|2022-08-22 22:31:31,385|Call of get_tick_data raised an error:
|ERROR|2022-08-22 22:31:31,385|<class 'AttributeError'>
|ERROR|2022-08-22 22:31:31,385|'DataFrame' object has no attribute 'concat'
|ERROR|2022-08-22 22:31:32,196|Call of get_tick_data raised an error:
|ERROR|2022-08-22 22:31:32,196|<class 'AttributeError'>
|ERROR|2022-08-22 22:31:32,196|'DataFrame' object has no attribute 'concat'
|ERROR|2022-08-22 22:31:32,831|Call of get_tick_data raised an error:
|ERROR|2022-08-22 22:31:32,832|<class 'AttributeError'>
|ERROR|2022-08-22 22:31:32,832|'DataFrame' object has no attribute 'concat'
|ERROR|2022-08-22 22:31:32,850|Call of get_tick_data raised an error:
|ERROR|2022-08-22 22:31:32,850|<class 'AttributeError'>
|ERROR|2022-08-22 22:31:32,851|'DataFrame' object has no attribute 'concat'
|ERROR|2022-08-22 22:37:35,519|Socket returns unknown error.
|ERROR|2022-08-22 22:42:00,128|Call of get_tick_data raised an error:
|ERROR|2022-08-22 22:42:00,128|<class 'KeyError'>
|ERROR|2022-08-22 22:42:00,128|Timestamp('2022-08-22 17:11:00')
|ERROR|2022-08-22 22:42:00,953|Call of get_tick_data raised an error:
|ERROR|2022-08-22 22:42:00,953|<class 'KeyError'>
|ERROR|2022-08-22 22:42:00,953|Timestamp('2022-08-22 17:11:00')
|ERROR|2022-08-22 22:42:01,457|Call of get_tick_data raised an error:
|ERROR|2022-08-22 22:42:01,457|<class 'KeyError'>
|ERROR|2022-08-22 22:42:01,457|Timestamp('2022-08-22 17:11:00')
|ERROR|2022-08-22 22:42:01,965|Call of get_tick_data raised an error:
|ERROR|2022-08-22 22:42:01,966|<class 'KeyError'>
|ERROR|2022-08-22 22:42:01,966|Timestamp('2022-08-22 17:11:00')
|ERROR|2022-08-22 22:42:02,683|Call of get_tick_data raised an error:
|ERROR|2022-08-22 22:42:02,683|<class 'KeyError'>
|ERROR|2022-08-22 22:42:02,683|Timestamp('2022-08-22 17:11:00')
|ERROR|2022-08-22 22:42:04,036|Call of get_tick_data raised an error:
|ERROR|2022-08-22 22:42:04,037|<class 'KeyError'>
|ERROR|2022-08-22 22:42:04,037|Timestamp('2022-08-22 17:11:00')
|ERROR|2022-08-22 22:42:05,017|Call of get_tick_data raised an error:
|ERROR|2022-08-22 22:42:05,017|<class 'KeyError'>
|ERROR|2022-08-22 22:42:05,018|Timestamp('2022-08-22 17:11:00')
|ERROR|2022-08-22 22:42:05,859|Call of get_tick_data raised an error:
|ERROR|2022-08-22 22:42:05,859|<class 'KeyError'>
|ERROR|2022-08-22 22:42:05,859|Timestamp('2022-08-22 17:11:00')
|ERROR|2022-08-22 22:42:06,682|Call of get_tick_data raised an error:
|ERROR|2022-08-22 22:42:06,683|<class 'KeyError'>
|ERROR|2022-08-22 22:42:06,683|Timestamp('2022-08-22 17:11:00')
|ERROR|2022-08-22 22:42:08,223|Call of get_tick_data raised an error:
|ERROR|2022-08-22 22:42:08,223|<class 'KeyError'>
|ERROR|2022-08-22 22:42:08,223|Timestamp('2022-08-22 17:11:00')
|ERROR|2022-08-22 22:42:09,872|Call of get_tick_data raised an error:
|ERROR|2022-08-22 22:42:09,872|<class 'KeyError'>
|ERROR|2022-08-22 22:42:09,872|Timestamp('2022-08-22 17:11:00')
|ERROR|2022-08-22 22:42:11,181|Call of get_tick_data raised an error:
|ERROR|2022-08-22 22:42:11,181|<class 'KeyError'>
|ERROR|2022-08-22 22:42:11,181|Timestamp('2022-08-22 17:11:00')
|ERROR|2022-08-22 22:42:12,210|Call of get_tick_data raised an error:
|ERROR|2022-08-22 22:42:12,210|<class 'KeyError'>
|ERROR|2022-08-22 22:42:12,210|Timestamp('2022-08-22 17:11:00')
|ERROR|2022-08-22 22:42:12,513|Call of get_tick_data raised an error:
|ERROR|2022-08-22 22:42:12,513|<class 'KeyError'>
|ERROR|2022-08-22 22:42:12,513|Timestamp('2022-08-22 17:11:00')
|ERROR|2022-08-22 22:42:15,791|Call of get_tick_data raised an error:
|ERROR|2022-08-22 22:42:15,792|<class 'KeyError'>
|ERROR|2022-08-22 22:42:15,792|Timestamp('2022-08-22 17:11:00')
|ERROR|2022-08-22 22:42:16,413|Call of get_tick_data raised an error:
|ERROR|2022-08-22 22:42:16,416|<class 'KeyError'>
|ERROR|2022-08-22 22:42:16,416|Timestamp('2022-08-22 17:11:00')
|ERROR|2022-08-22 22:42:19,082|Call of get_tick_data raised an error:
|ERROR|2022-08-22 22:42:19,082|<class 'KeyError'>
|ERROR|2022-08-22 22:42:19,082|Timestamp('2022-08-22 17:11:00')
|ERROR|2022-08-22 22:42:21,220|Call of get_tick_data raised an error:
|ERROR|2022-08-22 22:42:21,220|<class 'KeyError'>
|ERROR|2022-08-22 22:42:21,220|Timestamp('2022-08-22 17:11:00')
|ERROR|2022-08-22 22:42:21,871|Call of get_tick_data raised an error:
|ERROR|2022-08-22 22:42:21,871|<class 'KeyError'>
|ERROR|2022-08-22 22:42:21,871|Timestamp('2022-08-22 17:11:00')
|ERROR|2022-08-22 22:42:22,507|Call of get_tick_data raised an error:
|ERROR|2022-08-22 22:42:22,507|<class 'KeyError'>
|ERROR|2022-08-22 22:42:22,507|Timestamp('2022-08-22 17:11:00')
|ERROR|2022-08-22 22:42:23,573|Call of get_tick_data raised an error:
|ERROR|2022-08-22 22:42:23,574|<class 'KeyError'>
|ERROR|2022-08-22 22:42:23,574|Timestamp('2022-08-22 17:11:00')
|ERROR|2022-08-22 22:42:24,019|Call of get_tick_data raised an error:
|ERROR|2022-08-22 22:42:24,020|<class 'KeyError'>
|ERROR|2022-08-22 22:42:24,020|Timestamp('2022-08-22 17:11:00')
|ERROR|2022-08-22 22:42:25,006|Call of get_tick_data raised an error:
|ERROR|2022-08-22 22:42:25,006|<class 'KeyError'>
|ERROR|2022-08-22 22:42:25,006|Timestamp('2022-08-22 17:11:00')
|ERROR|2022-08-22 22:42:25,634|Call of get_tick_data raised an error:
|ERROR|2022-08-22 22:42:25,634|<class 'KeyError'>
|ERROR|2022-08-22 22:42:25,634|Timestamp('2022-08-22 17:11:00')
|ERROR|2022-08-22 22:42:26,304|Call of get_tick_data raised an error:
|ERROR|2022-08-22 22:42:26,304|<class 'KeyError'>
|ERROR|2022-08-22 22:42:26,304|Timestamp('2022-08-22 17:11:00')
|ERROR|2022-08-22 22:42:26,708|Call of get_tick_data raised an error:
|ERROR|2022-08-22 22:42:26,708|<class 'KeyError'>
|ERROR|2022-08-22 22:42:26,708|Timestamp('2022-08-22 17:11:00')
|ERROR|2022-08-22 22:42:27,898|Call of get_tick_data raised an error:
|ERROR|2022-08-22 22:42:27,898|<class 'KeyError'>
|ERROR|2022-08-22 22:42:27,898|Timestamp('2022-08-22 17:11:00')
|ERROR|2022-08-22 22:42:28,284|Call of get_tick_data raised an error:
|ERROR|2022-08-22 22:42:28,285|<class 'KeyError'>
|ERROR|2022-08-22 22:42:28,286|Timestamp('2022-08-22 17:11:00')
|ERROR|2022-08-22 22:42:28,588|Call of get_tick_data raised an error:
|ERROR|2022-08-22 22:42:28,588|<class 'KeyError'>
|ERROR|2022-08-22 22:42:28,588|Timestamp('2022-08-22 17:11:00')
|ERROR|2022-08-22 22:42:31,470|Call of get_tick_data raised an error:
|ERROR|2022-08-22 22:42:31,470|<class 'KeyError'>
|ERROR|2022-08-22 22:42:31,470|Timestamp('2022-08-22 17:11:00')
|ERROR|2022-08-22 22:42:32,624|Call of get_tick_data raised an error:
|ERROR|2022-08-22 22:42:32,624|<class 'KeyError'>
|ERROR|2022-08-22 22:42:32,624|Timestamp('2022-08-22 17:11:00')
|ERROR|2022-08-22 22:42:32,635|Call of get_tick_data raised an error:
|ERROR|2022-08-22 22:42:32,635|<class 'KeyError'>
|ERROR|2022-08-22 22:42:32,635|Timestamp('2022-08-22 17:11:00')
|ERROR|2022-08-22 22:42:32,649|Call of get_tick_data raised an error:
|ERROR|2022-08-22 22:42:32,649|<class 'KeyError'>
|ERROR|2022-08-22 22:42:32,649|Timestamp('2022-08-22 17:11:00')
|ERROR|2022-08-22 22:42:33,037|Call of get_tick_data raised an error:
|ERROR|2022-08-22 22:42:33,037|<class 'KeyError'>
|ERROR|2022-08-22 22:42:33,037|Timestamp('2022-08-22 17:11:00')
|ERROR|2022-08-22 22:42:33,918|Call of get_tick_data raised an error:
|ERROR|2022-08-22 22:42:33,918|<class 'KeyError'>
|ERROR|2022-08-22 22:42:33,919|Timestamp('2022-08-22 17:11:00')
|ERROR|2022-08-22 22:42:34,888|Call of get_tick_data raised an error:
|ERROR|2022-08-22 22:42:34,888|<class 'KeyError'>
|ERROR|2022-08-22 22:42:34,888|Timestamp('2022-08-22 17:11:00')
|ERROR|2022-08-22 22:42:35,351|Call of get_tick_data raised an error:
|ERROR|2022-08-22 22:42:35,352|<class 'KeyError'>
|ERROR|2022-08-22 22:42:35,352|Timestamp('2022-08-22 17:11:00')
|ERROR|2022-08-22 22:42:35,797|Call of get_tick_data raised an error:
|ERROR|2022-08-22 22:42:35,798|<class 'KeyError'>
|ERROR|2022-08-22 22:42:35,798|Timestamp('2022-08-22 17:11:00')
|ERROR|2022-08-22 22:42:36,578|Call of get_tick_data raised an error:
|ERROR|2022-08-22 22:42:36,579|<class 'KeyError'>
|ERROR|2022-08-22 22:42:36,579|Timestamp('2022-08-22 17:11:00')
|ERROR|2022-08-22 22:42:36,761|Call of get_tick_data raised an error:
|ERROR|2022-08-22 22:42:36,761|<class 'KeyError'>
|ERROR|2022-08-22 22:42:36,761|Timestamp('2022-08-22 17:11:00')
|ERROR|2022-08-22 22:42:38,968|Call of get_tick_data raised an error:
|ERROR|2022-08-22 22:42:38,968|<class 'KeyError'>
|ERROR|2022-08-22 22:42:38,968|Timestamp('2022-08-22 17:11:00')
|ERROR|2022-08-22 22:42:39,750|Call of get_tick_data raised an error:
|ERROR|2022-08-22 22:42:39,750|<class 'KeyError'>
|ERROR|2022-08-22 22:42:39,751|Timestamp('2022-08-22 17:11:00')
|ERROR|2022-08-22 22:42:40,268|Call of get_tick_data raised an error:
|ERROR|2022-08-22 22:42:40,268|<class 'KeyError'>
|ERROR|2022-08-22 22:42:40,268|Timestamp('2022-08-22 17:11:00')
|ERROR|2022-08-22 22:42:42,780|Call of get_tick_data raised an error:
|ERROR|2022-08-22 22:42:42,780|<class 'KeyError'>
|ERROR|2022-08-22 22:42:42,780|Timestamp('2022-08-22 17:11:00')
|ERROR|2022-08-22 22:42:44,997|Call of get_tick_data raised an error:
|ERROR|2022-08-22 22:42:44,997|<class 'KeyError'>
|ERROR|2022-08-22 22:42:44,998|Timestamp('2022-08-22 17:11:00')
|ERROR|2022-08-22 22:42:45,011|Call of get_tick_data raised an error:
|ERROR|2022-08-22 22:42:45,011|<class 'KeyError'>
|ERROR|2022-08-22 22:42:45,011|Timestamp('2022-08-22 17:11:00')
|ERROR|2022-08-22 22:42:46,842|Call of get_tick_data raised an error:
|ERROR|2022-08-22 22:42:46,842|<class 'KeyError'>
|ERROR|2022-08-22 22:42:46,842|Timestamp('2022-08-22 17:11:00')
|ERROR|2022-08-22 22:42:47,766|Call of get_tick_data raised an error:
|ERROR|2022-08-22 22:42:47,766|<class 'KeyError'>
|ERROR|2022-08-22 22:42:47,766|Timestamp('2022-08-22 17:11:00')
|ERROR|2022-08-22 22:42:47,779|Call of get_tick_data raised an error:
|ERROR|2022-08-22 22:42:47,779|<class 'KeyError'>
|ERROR|2022-08-22 22:42:47,779|Timestamp('2022-08-22 17:11:00')
|ERROR|2022-08-22 22:42:48,770|Call of get_tick_data raised an error:
|ERROR|2022-08-22 22:42:48,772|<class 'KeyError'>
|ERROR|2022-08-22 22:42:48,772|Timestamp('2022-08-22 17:11:00')
|ERROR|2022-08-22 22:42:49,296|Call of get_tick_data raised an error:
|ERROR|2022-08-22 22:42:49,297|<class 'KeyError'>
|ERROR|2022-08-22 22:42:49,297|Timestamp('2022-08-22 17:11:00')
|ERROR|2022-08-22 22:42:49,888|Call of get_tick_data raised an error:
|ERROR|2022-08-22 22:42:49,888|<class 'KeyError'>
|ERROR|2022-08-22 22:42:49,888|Timestamp('2022-08-22 17:11:00')
|ERROR|2022-08-22 22:43:21,994|Connection error: HTTPSConnectionPool(host='api-demo.fxcm.com', port=443): Read timed out. (read timeout=5)
|ERROR|2022-08-22 22:43:21,995|Socket returns unknown error.
|ERROR|2022-08-22 22:45:21,522|Socket returns unknown error.
|ERROR|2022-08-22 23:02:40,716|Connection error: HTTPSConnectionPool(host='api-demo.fxcm.com', port=443): Read timed out. (read timeout=5)
|ERROR|2022-08-22 23:02:40,716|Socket returns unknown error.
|ERROR|2022-08-22 23:15:07,853|Call of get_tick_data raised an error:
|ERROR|2022-08-22 23:15:07,854|<class 'requests.exceptions.ConnectionError'>
|ERROR|2022-08-22 23:15:07,854|('Connection aborted.', ConnectionResetError(10054, 'An existing connection was forcibly closed by the remote host', None, 10054, None))
|ERROR|2022-08-22 23:29:25,823|Server reports an error: {'executed': False, 'error': 'Unauthorized'}.
|ERROR|2022-08-22 23:29:25,823|URL: https://api-demo.fxcm.com:443/trading/get_model?models=Account
|ERROR|2022-08-22 23:29:25,824|Headers: {'User-Agent': 'request', 'Accept-Encoding': 'gzip, deflate, br', 'Accept': 'application/json', 'Connection': 'keep-alive', 'Authorization': 'Bearer 3QY2PaRd6hRZyvBMApuk97d9d09d13219a0032426fdcf1fe18e656f91a05', 'Content-Type': 'application/x-www-form-urlencoded'}
|ERROR|2022-08-22 23:29:25,824|Params: {'models': ['Account']}
|ERROR|2022-08-22 23:29:25,824|Bearer token: Bearer 3QY2PaRd6hRZyvBMApuk97d9d09d13219a0032426fdcf1fe18e656f91a05
|ERROR|2022-08-22 23:29:25,824|Connection status: established
|ERROR|2022-08-22 23:29:25,824|Socket session id: 3QY2PaRd6hRZyvBMApuk
|ERROR|2022-08-22 23:29:25,824|Can not parse server answer to json object: {"response":{"executed":false,"error":"Unauthorized"}}.
|ERROR|2022-08-22 23:30:53,230|Socket returns unknown error.
|ERROR|2022-08-22 23:31:08,188|Socket returns unknown error.
|ERROR|2022-08-22 23:45:25,781|packet queue is empty, aborting
|ERROR|2022-08-22 23:45:43,333|Connection error: HTTPSConnectionPool(host='api-demo.fxcm.com', port=443): Read timed out. (read timeout=5)
|ERROR|2022-08-22 23:45:45,640|Connection error: HTTPSConnectionPool(host='api-demo.fxcm.com', port=443): Max retries exceeded with url: /socket.io/?access_token=97d9d09d13219a0032426fdcf1fe18e656f91a05&agent=pythonquants&wait_for_connection=False&transport=polling&EIO=4&t=1661192145.6185331 (Caused by NewConnectionError('<urllib3.connection.HTTPSConnection object at 0x00000103B45BB0D0>: Failed to establish a new connection: [Errno 11001] getaddrinfo failed'))
|ERROR|2022-08-22 23:45:49,565|Connection error: HTTPSConnectionPool(host='api-demo.fxcm.com', port=443): Max retries exceeded with url: /socket.io/?access_token=97d9d09d13219a0032426fdcf1fe18e656f91a05&agent=pythonquants&wait_for_connection=False&transport=polling&EIO=4&t=1661192149.5581284 (Caused by NewConnectionError('<urllib3.connection.HTTPSConnection object at 0x00000103B45BB130>: Failed to establish a new connection: [Errno 11001] getaddrinfo failed'))
|ERROR|2022-08-22 23:45:54,945|Connection error: HTTPSConnectionPool(host='api-demo.fxcm.com', port=443): Max retries exceeded with url: /socket.io/?access_token=97d9d09d13219a0032426fdcf1fe18e656f91a05&agent=pythonquants&wait_for_connection=False&transport=polling&EIO=4&t=1661192154.9386775 (Caused by NewConnectionError('<urllib3.connection.HTTPSConnection object at 0x00000103B45BB0D0>: Failed to establish a new connection: [Errno 11001] getaddrinfo failed'))
|ERROR|2022-08-22 23:46:00,189|Connection error: HTTPSConnectionPool(host='api-demo.fxcm.com', port=443): Max retries exceeded with url: /socket.io/?access_token=97d9d09d13219a0032426fdcf1fe18e656f91a05&agent=pythonquants&wait_for_connection=False&transport=polling&EIO=4&t=1661192160.1692863 (Caused by NewConnectionError('<urllib3.connection.HTTPSConnection object at 0x00000103B45BB130>: Failed to establish a new connection: [Errno 11001] getaddrinfo failed'))
|ERROR|2022-08-22 23:46:05,584|Connection error: HTTPSConnectionPool(host='api-demo.fxcm.com', port=443): Max retries exceeded with url: /socket.io/?access_token=97d9d09d13219a0032426fdcf1fe18e656f91a05&agent=pythonquants&wait_for_connection=False&transport=polling&EIO=4&t=1661192165.5773816 (Caused by NewConnectionError('<urllib3.connection.HTTPSConnection object at 0x00000103B45BB130>: Failed to establish a new connection: [Errno 11001] getaddrinfo failed'))
|ERROR|2022-08-22 23:46:10,277|Connection error: HTTPSConnectionPool(host='api-demo.fxcm.com', port=443): Max retries exceeded with url: /socket.io/?access_token=97d9d09d13219a0032426fdcf1fe18e656f91a05&agent=pythonquants&wait_for_connection=False&transport=polling&EIO=4&t=1661192170.269569 (Caused by NewConnectionError('<urllib3.connection.HTTPSConnection object at 0x00000103B45BB3A0>: Failed to establish a new connection: [Errno 11001] getaddrinfo failed'))
|ERROR|2022-08-22 23:46:15,262|Connection error: HTTPSConnectionPool(host='api-demo.fxcm.com', port=443): Max retries exceeded with url: /socket.io/?access_token=97d9d09d13219a0032426fdcf1fe18e656f91a05&agent=pythonquants&wait_for_connection=False&transport=polling&EIO=4&t=1661192175.2404137 (Caused by NewConnectionError('<urllib3.connection.HTTPSConnection object at 0x00000103B45BB130>: Failed to establish a new connection: [Errno 11001] getaddrinfo failed'))
|ERROR|2022-08-22 23:46:20,389|Connection error: HTTPSConnectionPool(host='api-demo.fxcm.com', port=443): Max retries exceeded with url: /socket.io/?access_token=97d9d09d13219a0032426fdcf1fe18e656f91a05&agent=pythonquants&wait_for_connection=False&transport=polling&EIO=4&t=1661192180.3821237 (Caused by NewConnectionError('<urllib3.connection.HTTPSConnection object at 0x00000103B45BB3A0>: Failed to establish a new connection: [Errno 11001] getaddrinfo failed'))
|ERROR|2022-08-22 23:46:25,292|Connection error: HTTPSConnectionPool(host='api-demo.fxcm.com', port=443): Max retries exceeded with url: /socket.io/?access_token=97d9d09d13219a0032426fdcf1fe18e656f91a05&agent=pythonquants&wait_for_connection=False&transport=polling&EIO=4&t=1661192185.2854002 (Caused by NewConnectionError('<urllib3.connection.HTTPSConnection object at 0x00000103B45BB130>: Failed to establish a new connection: [Errno 11001] getaddrinfo failed'))
|ERROR|2022-08-22 23:46:30,178|Connection error: HTTPSConnectionPool(host='api-demo.fxcm.com', port=443): Max retries exceeded with url: /socket.io/?access_token=97d9d09d13219a0032426fdcf1fe18e656f91a05&agent=pythonquants&wait_for_connection=False&transport=polling&EIO=4&t=1661192190.1705556 (Caused by NewConnectionError('<urllib3.connection.HTTPSConnection object at 0x00000103B45BB3A0>: Failed to establish a new connection: [Errno 11001] getaddrinfo failed'))
|ERROR|2022-08-22 23:46:35,469|Connection error: HTTPSConnectionPool(host='api-demo.fxcm.com', port=443): Max retries exceeded with url: /socket.io/?access_token=97d9d09d13219a0032426fdcf1fe18e656f91a05&agent=pythonquants&wait_for_connection=False&transport=polling&EIO=4&t=1661192195.4620795 (Caused by NewConnectionError('<urllib3.connection.HTTPSConnection object at 0x00000103B45BB130>: Failed to establish a new connection: [Errno 11001] getaddrinfo failed'))
|ERROR|2022-08-22 23:46:40,128|Connection error: HTTPSConnectionPool(host='api-demo.fxcm.com', port=443): Max retries exceeded with url: /socket.io/?access_token=97d9d09d13219a0032426fdcf1fe18e656f91a05&agent=pythonquants&wait_for_connection=False&transport=polling&EIO=4&t=1661192200.121862 (Caused by NewConnectionError('<urllib3.connection.HTTPSConnection object at 0x00000103B45BB3A0>: Failed to establish a new connection: [Errno 11001] getaddrinfo failed'))
|ERROR|2022-08-22 23:46:44,791|Connection error: HTTPSConnectionPool(host='api-demo.fxcm.com', port=443): Max retries exceeded with url: /socket.io/?access_token=97d9d09d13219a0032426fdcf1fe18e656f91a05&agent=pythonquants&wait_for_connection=False&transport=polling&EIO=4&t=1661192204.7837017 (Caused by NewConnectionError('<urllib3.connection.HTTPSConnection object at 0x00000103B45BB130>: Failed to establish a new connection: [Errno 11001] getaddrinfo failed'))
|ERROR|2022-08-22 23:46:49,687|Connection error: HTTPSConnectionPool(host='api-demo.fxcm.com', port=443): Max retries exceeded with url: /socket.io/?access_token=97d9d09d13219a0032426fdcf1fe18e656f91a05&agent=pythonquants&wait_for_connection=False&transport=polling&EIO=4&t=1661192209.680596 (Caused by NewConnectionError('<urllib3.connection.HTTPSConnection object at 0x00000103B45BB3A0>: Failed to establish a new connection: [Errno 11001] getaddrinfo failed'))
|ERROR|2022-08-22 23:46:54,918|Connection error: HTTPSConnectionPool(host='api-demo.fxcm.com', port=443): Max retries exceeded with url: /socket.io/?access_token=97d9d09d13219a0032426fdcf1fe18e656f91a05&agent=pythonquants&wait_for_connection=False&transport=polling&EIO=4&t=1661192214.9111245 (Caused by NewConnectionError('<urllib3.connection.HTTPSConnection object at 0x00000103B45BB130>: Failed to establish a new connection: [Errno 11001] getaddrinfo failed'))
|ERROR|2022-08-22 23:46:59,456|Connection error: HTTPSConnectionPool(host='api-demo.fxcm.com', port=443): Max retries exceeded with url: /socket.io/?access_token=97d9d09d13219a0032426fdcf1fe18e656f91a05&agent=pythonquants&wait_for_connection=False&transport=polling&EIO=4&t=1661192219.449377 (Caused by NewConnectionError('<urllib3.connection.HTTPSConnection object at 0x00000103B45BB3A0>: Failed to establish a new connection: [Errno 11001] getaddrinfo failed'))
|ERROR|2022-08-22 23:47:04,271|Connection error: HTTPSConnectionPool(host='api-demo.fxcm.com', port=443): Max retries exceeded with url: /socket.io/?access_token=97d9d09d13219a0032426fdcf1fe18e656f91a05&agent=pythonquants&wait_for_connection=False&transport=polling&EIO=4&t=1661192224.264593 (Caused by NewConnectionError('<urllib3.connection.HTTPSConnection object at 0x00000103B45BB130>: Failed to establish a new connection: [Errno 11001] getaddrinfo failed'))
|ERROR|2022-08-22 23:47:09,709|Connection error: HTTPSConnectionPool(host='api-demo.fxcm.com', port=443): Max retries exceeded with url: /socket.io/?access_token=97d9d09d13219a0032426fdcf1fe18e656f91a05&agent=pythonquants&wait_for_connection=False&transport=polling&EIO=4&t=1661192229.7039754 (Caused by NewConnectionError('<urllib3.connection.HTTPSConnection object at 0x00000103B45BB3A0>: Failed to establish a new connection: [Errno 11001] getaddrinfo failed'))
|ERROR|2022-08-22 23:47:14,536|Connection error: HTTPSConnectionPool(host='api-demo.fxcm.com', port=443): Max retries exceeded with url: /socket.io/?access_token=97d9d09d13219a0032426fdcf1fe18e656f91a05&agent=pythonquants&wait_for_connection=False&transport=polling&EIO=4&t=1661192234.5349731 (Caused by NewConnectionError('<urllib3.connection.HTTPSConnection object at 0x00000103B45BB130>: Failed to establish a new connection: [Errno 11001] getaddrinfo failed'))
|ERROR|2022-08-22 23:47:19,697|Connection error: HTTPSConnectionPool(host='api-demo.fxcm.com', port=443): Max retries exceeded with url: /socket.io/?access_token=97d9d09d13219a0032426fdcf1fe18e656f91a05&agent=pythonquants&wait_for_connection=False&transport=polling&EIO=4&t=1661192239.6919212 (Caused by NewConnectionError('<urllib3.connection.HTTPSConnection object at 0x00000103B45BB3A0>: Failed to establish a new connection: [Errno 11001] getaddrinfo failed'))
|ERROR|2022-08-22 23:47:24,308|Connection error: HTTPSConnectionPool(host='api-demo.fxcm.com', port=443): Max retries exceeded with url: /socket.io/?access_token=97d9d09d13219a0032426fdcf1fe18e656f91a05&agent=pythonquants&wait_for_connection=False&transport=polling&EIO=4&t=1661192244.3038867 (Caused by NewConnectionError('<urllib3.connection.HTTPSConnection object at 0x00000103B45BB130>: Failed to establish a new connection: [Errno 11001] getaddrinfo failed'))
|ERROR|2022-08-22 23:47:28,985|Connection error: HTTPSConnectionPool(host='api-demo.fxcm.com', port=443): Max retries exceeded with url: /socket.io/?access_token=97d9d09d13219a0032426fdcf1fe18e656f91a05&agent=pythonquants&wait_for_connection=False&transport=polling&EIO=4&t=1661192248.977324 (Caused by NewConnectionError('<urllib3.connection.HTTPSConnection object at 0x00000103B45BB3A0>: Failed to establish a new connection: [Errno 11001] getaddrinfo failed'))
|ERROR|2022-08-22 23:47:33,608|Connection error: HTTPSConnectionPool(host='api-demo.fxcm.com', port=443): Max retries exceeded with url: /socket.io/?access_token=97d9d09d13219a0032426fdcf1fe18e656f91a05&agent=pythonquants&wait_for_connection=False&transport=polling&EIO=4&t=1661192253.6008892 (Caused by NewConnectionError('<urllib3.connection.HTTPSConnection object at 0x00000103B45BB130>: Failed to establish a new connection: [Errno 11001] getaddrinfo failed'))
|ERROR|2022-08-22 23:47:38,936|Connection error: HTTPSConnectionPool(host='api-demo.fxcm.com', port=443): Max retries exceeded with url: /socket.io/?access_token=97d9d09d13219a0032426fdcf1fe18e656f91a05&agent=pythonquants&wait_for_connection=False&transport=polling&EIO=4&t=1661192258.9332771 (Caused by NewConnectionError('<urllib3.connection.HTTPSConnection object at 0x00000103B45BB3A0>: Failed to establish a new connection: [Errno 11001] getaddrinfo failed'))
|ERROR|2022-08-22 23:47:44,030|Connection error: HTTPSConnectionPool(host='api-demo.fxcm.com', port=443): Max retries exceeded with url: /socket.io/?access_token=97d9d09d13219a0032426fdcf1fe18e656f91a05&agent=pythonquants&wait_for_connection=False&transport=polling&EIO=4&t=1661192264.0231173 (Caused by NewConnectionError('<urllib3.connection.HTTPSConnection object at 0x00000103B45BB130>: Failed to establish a new connection: [Errno 11001] getaddrinfo failed'))
|ERROR|2022-08-22 23:47:48,706|Connection error: HTTPSConnectionPool(host='api-demo.fxcm.com', port=443): Max retries exceeded with url: /socket.io/?access_token=97d9d09d13219a0032426fdcf1fe18e656f91a05&agent=pythonquants&wait_for_connection=False&transport=polling&EIO=4&t=1661192268.6980543 (Caused by NewConnectionError('<urllib3.connection.HTTPSConnection object at 0x00000103B45BB3A0>: Failed to establish a new connection: [Errno 11001] getaddrinfo failed'))
|ERROR|2022-08-22 23:47:53,676|Connection error: HTTPSConnectionPool(host='api-demo.fxcm.com', port=443): Max retries exceeded with url: /socket.io/?access_token=97d9d09d13219a0032426fdcf1fe18e656f91a05&agent=pythonquants&wait_for_connection=False&transport=polling&EIO=4&t=1661192273.6680582 (Caused by NewConnectionError('<urllib3.connection.HTTPSConnection object at 0x00000103B45BB130>: Failed to establish a new connection: [Errno 11001] getaddrinfo failed'))
|ERROR|2022-08-22 23:47:58,749|Connection error: HTTPSConnectionPool(host='api-demo.fxcm.com', port=443): Max retries exceeded with url: /socket.io/?access_token=97d9d09d13219a0032426fdcf1fe18e656f91a05&agent=pythonquants&wait_for_connection=False&transport=polling&EIO=4&t=1661192278.7450743 (Caused by NewConnectionError('<urllib3.connection.HTTPSConnection object at 0x00000103B45BB3A0>: Failed to establish a new connection: [Errno 11001] getaddrinfo failed'))
|ERROR|2022-08-22 23:48:03,776|Connection error: HTTPSConnectionPool(host='api-demo.fxcm.com', port=443): Max retries exceeded with url: /socket.io/?access_token=97d9d09d13219a0032426fdcf1fe18e656f91a05&agent=pythonquants&wait_for_connection=False&transport=polling&EIO=4&t=1661192283.7692955 (Caused by NewConnectionError('<urllib3.connection.HTTPSConnection object at 0x00000103B45BB130>: Failed to establish a new connection: [Errno 11001] getaddrinfo failed'))
|ERROR|2022-08-22 23:48:09,113|Connection error: HTTPSConnectionPool(host='api-demo.fxcm.com', port=443): Max retries exceeded with url: /socket.io/?access_token=97d9d09d13219a0032426fdcf1fe18e656f91a05&agent=pythonquants&wait_for_connection=False&transport=polling&EIO=4&t=1661192289.097169 (Caused by NewConnectionError('<urllib3.connection.HTTPSConnection object at 0x00000103B45BB3A0>: Failed to establish a new connection: [Errno 11001] getaddrinfo failed'))
|ERROR|2022-08-22 23:48:14,279|Connection error: HTTPSConnectionPool(host='api-demo.fxcm.com', port=443): Max retries exceeded with url: /socket.io/?access_token=97d9d09d13219a0032426fdcf1fe18e656f91a05&agent=pythonquants&wait_for_connection=False&transport=polling&EIO=4&t=1661192294.2729359 (Caused by NewConnectionError('<urllib3.connection.HTTPSConnection object at 0x00000103B45BB9A0>: Failed to establish a new connection: [Errno 11001] getaddrinfo failed'))
|ERROR|2022-08-22 23:48:18,847|Connection error: HTTPSConnectionPool(host='api-demo.fxcm.com', port=443): Max retries exceeded with url: /socket.io/?access_token=97d9d09d13219a0032426fdcf1fe18e656f91a05&agent=pythonquants&wait_for_connection=False&transport=polling&EIO=4&t=1661192298.840278 (Caused by NewConnectionError('<urllib3.connection.HTTPSConnection object at 0x00000103B45BB3A0>: Failed to establish a new connection: [Errno 11001] getaddrinfo failed'))
|ERROR|2022-08-22 23:48:23,383|Connection error: HTTPSConnectionPool(host='api-demo.fxcm.com', port=443): Max retries exceeded with url: /socket.io/?access_token=97d9d09d13219a0032426fdcf1fe18e656f91a05&agent=pythonquants&wait_for_connection=False&transport=polling&EIO=4&t=1661192303.3762674 (Caused by NewConnectionError('<urllib3.connection.HTTPSConnection object at 0x00000103B45BB9A0>: Failed to establish a new connection: [Errno 11001] getaddrinfo failed'))
|ERROR|2022-08-22 23:48:27,949|Connection error: HTTPSConnectionPool(host='api-demo.fxcm.com', port=443): Max retries exceeded with url: /socket.io/?access_token=97d9d09d13219a0032426fdcf1fe18e656f91a05&agent=pythonquants&wait_for_connection=False&transport=polling&EIO=4&t=1661192307.942069 (Caused by NewConnectionError('<urllib3.connection.HTTPSConnection object at 0x00000103B45BB3A0>: Failed to establish a new connection: [Errno 11001] getaddrinfo failed'))
|ERROR|2022-08-22 23:48:32,816|Connection error: HTTPSConnectionPool(host='api-demo.fxcm.com', port=443): Max retries exceeded with url: /socket.io/?access_token=97d9d09d13219a0032426fdcf1fe18e656f91a05&agent=pythonquants&wait_for_connection=False&transport=polling&EIO=4&t=1661192312.8100874 (Caused by NewConnectionError('<urllib3.connection.HTTPSConnection object at 0x00000103B45BB9A0>: Failed to establish a new connection: [Errno 11001] getaddrinfo failed'))
|ERROR|2022-08-22 23:48:38,287|Connection error: HTTPSConnectionPool(host='api-demo.fxcm.com', port=443): Max retries exceeded with url: /socket.io/?access_token=97d9d09d13219a0032426fdcf1fe18e656f91a05&agent=pythonquants&wait_for_connection=False&transport=polling&EIO=4&t=1661192318.2806895 (Caused by NewConnectionError('<urllib3.connection.HTTPSConnection object at 0x00000103B45BB3A0>: Failed to establish a new connection: [Errno 11001] getaddrinfo failed'))
|ERROR|2022-08-22 23:48:43,238|Connection error: HTTPSConnectionPool(host='api-demo.fxcm.com', port=443): Max retries exceeded with url: /socket.io/?access_token=97d9d09d13219a0032426fdcf1fe18e656f91a05&agent=pythonquants&wait_for_connection=False&transport=polling&EIO=4&t=1661192323.231303 (Caused by NewConnectionError('<urllib3.connection.HTTPSConnection object at 0x00000103B45BB9A0>: Failed to establish a new connection: [Errno 11001] getaddrinfo failed'))
|ERROR|2022-08-22 23:48:48,244|Connection error: HTTPSConnectionPool(host='api-demo.fxcm.com', port=443): Max retries exceeded with url: /socket.io/?access_token=97d9d09d13219a0032426fdcf1fe18e656f91a05&agent=pythonquants&wait_for_connection=False&transport=polling&EIO=4&t=1661192328.236896 (Caused by NewConnectionError('<urllib3.connection.HTTPSConnection object at 0x00000103B45BB3A0>: Failed to establish a new connection: [Errno 11001] getaddrinfo failed'))
|ERROR|2022-08-22 23:48:52,974|Connection error: HTTPSConnectionPool(host='api-demo.fxcm.com', port=443): Max retries exceeded with url: /socket.io/?access_token=97d9d09d13219a0032426fdcf1fe18e656f91a05&agent=pythonquants&wait_for_connection=False&transport=polling&EIO=4&t=1661192332.9673736 (Caused by NewConnectionError('<urllib3.connection.HTTPSConnection object at 0x00000103B45BB9A0>: Failed to establish a new connection: [Errno 11001] getaddrinfo failed'))
|ERROR|2022-08-22 23:48:58,191|Connection error: HTTPSConnectionPool(host='api-demo.fxcm.com', port=443): Max retries exceeded with url: /socket.io/?access_token=97d9d09d13219a0032426fdcf1fe18e656f91a05&agent=pythonquants&wait_for_connection=False&transport=polling&EIO=4&t=1661192338.1843886 (Caused by NewConnectionError('<urllib3.connection.HTTPSConnection object at 0x00000103B45BB3A0>: Failed to establish a new connection: [Errno 11001] getaddrinfo failed'))
|ERROR|2022-08-22 23:49:03,277|Connection error: HTTPSConnectionPool(host='api-demo.fxcm.com', port=443): Max retries exceeded with url: /socket.io/?access_token=97d9d09d13219a0032426fdcf1fe18e656f91a05&agent=pythonquants&wait_for_connection=False&transport=polling&EIO=4&t=1661192343.2720907 (Caused by NewConnectionError('<urllib3.connection.HTTPSConnection object at 0x00000103B45BB9A0>: Failed to establish a new connection: [Errno 11001] getaddrinfo failed'))
|ERROR|2022-08-22 23:49:08,451|Connection error: HTTPSConnectionPool(host='api-demo.fxcm.com', port=443): Max retries exceeded with url: /socket.io/?access_token=97d9d09d13219a0032426fdcf1fe18e656f91a05&agent=pythonquants&wait_for_connection=False&transport=polling&EIO=4&t=1661192348.4481704 (Caused by NewConnectionError('<urllib3.connection.HTTPSConnection object at 0x00000103B45BB3A0>: Failed to establish a new connection: [Errno 11001] getaddrinfo failed'))
|ERROR|2022-08-22 23:49:13,111|Connection error: HTTPSConnectionPool(host='api-demo.fxcm.com', port=443): Max retries exceeded with url: /socket.io/?access_token=97d9d09d13219a0032426fdcf1fe18e656f91a05&agent=pythonquants&wait_for_connection=False&transport=polling&EIO=4&t=1661192353.1047542 (Caused by NewConnectionError('<urllib3.connection.HTTPSConnection object at 0x00000103B45BB9A0>: Failed to establish a new connection: [Errno 11001] getaddrinfo failed'))
|ERROR|2022-08-22 23:49:17,935|Connection error: HTTPSConnectionPool(host='api-demo.fxcm.com', port=443): Max retries exceeded with url: /socket.io/?access_token=97d9d09d13219a0032426fdcf1fe18e656f91a05&agent=pythonquants&wait_for_connection=False&transport=polling&EIO=4&t=1661192357.9288077 (Caused by NewConnectionError('<urllib3.connection.HTTPSConnection object at 0x00000103B45BB3A0>: Failed to establish a new connection: [Errno 11001] getaddrinfo failed'))
|ERROR|2022-08-22 23:49:22,716|Connection error: HTTPSConnectionPool(host='api-demo.fxcm.com', port=443): Max retries exceeded with url: /socket.io/?access_token=97d9d09d13219a0032426fdcf1fe18e656f91a05&agent=pythonquants&wait_for_connection=False&transport=polling&EIO=4&t=1661192362.708909 (Caused by NewConnectionError('<urllib3.connection.HTTPSConnection object at 0x00000103B45BB9A0>: Failed to establish a new connection: [Errno 11001] getaddrinfo failed'))
|ERROR|2022-08-22 23:49:27,636|Connection error: HTTPSConnectionPool(host='api-demo.fxcm.com', port=443): Max retries exceeded with url: /socket.io/?access_token=97d9d09d13219a0032426fdcf1fe18e656f91a05&agent=pythonquants&wait_for_connection=False&transport=polling&EIO=4&t=1661192367.6341445 (Caused by NewConnectionError('<urllib3.connection.HTTPSConnection object at 0x00000103B45BB3A0>: Failed to establish a new connection: [Errno 11001] getaddrinfo failed'))
|ERROR|2022-08-22 23:49:32,181|Connection error: HTTPSConnectionPool(host='api-demo.fxcm.com', port=443): Max retries exceeded with url: /socket.io/?access_token=97d9d09d13219a0032426fdcf1fe18e656f91a05&agent=pythonquants&wait_for_connection=False&transport=polling&EIO=4&t=1661192372.1743639 (Caused by NewConnectionError('<urllib3.connection.HTTPSConnection object at 0x00000103B45BB9A0>: Failed to establish a new connection: [Errno 11001] getaddrinfo failed'))
|ERROR|2022-08-22 23:49:37,042|Connection error: HTTPSConnectionPool(host='api-demo.fxcm.com', port=443): Max retries exceeded with url: /socket.io/?access_token=97d9d09d13219a0032426fdcf1fe18e656f91a05&agent=pythonquants&wait_for_connection=False&transport=polling&EIO=4&t=1661192377.0340621 (Caused by NewConnectionError('<urllib3.connection.HTTPSConnection object at 0x00000103B45BB3A0>: Failed to establish a new connection: [Errno 11001] getaddrinfo failed'))
|ERROR|2022-08-22 23:49:41,620|Connection error: HTTPSConnectionPool(host='api-demo.fxcm.com', port=443): Max retries exceeded with url: /socket.io/?access_token=97d9d09d13219a0032426fdcf1fe18e656f91a05&agent=pythonquants&wait_for_connection=False&transport=polling&EIO=4&t=1661192381.6126783 (Caused by NewConnectionError('<urllib3.connection.HTTPSConnection object at 0x00000103B45BB9A0>: Failed to establish a new connection: [Errno 11001] getaddrinfo failed'))
|ERROR|2022-08-22 23:49:46,379|Connection error: HTTPSConnectionPool(host='api-demo.fxcm.com', port=443): Max retries exceeded with url: /socket.io/?access_token=97d9d09d13219a0032426fdcf1fe18e656f91a05&agent=pythonquants&wait_for_connection=False&transport=polling&EIO=4&t=1661192386.3719616 (Caused by NewConnectionError('<urllib3.connection.HTTPSConnection object at 0x00000103B45BB3A0>: Failed to establish a new connection: [Errno 11001] getaddrinfo failed'))
|ERROR|2022-08-22 23:49:51,283|Connection error: HTTPSConnectionPool(host='api-demo.fxcm.com', port=443): Max retries exceeded with url: /socket.io/?access_token=97d9d09d13219a0032426fdcf1fe18e656f91a05&agent=pythonquants&wait_for_connection=False&transport=polling&EIO=4&t=1661192391.2768705 (Caused by NewConnectionError('<urllib3.connection.HTTPSConnection object at 0x00000103B45BB9A0>: Failed to establish a new connection: [Errno 11001] getaddrinfo failed'))
|ERROR|2022-08-22 23:49:56,053|Connection error: HTTPSConnectionPool(host='api-demo.fxcm.com', port=443): Max retries exceeded with url: /socket.io/?access_token=97d9d09d13219a0032426fdcf1fe18e656f91a05&agent=pythonquants&wait_for_connection=False&transport=polling&EIO=4&t=1661192396.0461173 (Caused by NewConnectionError('<urllib3.connection.HTTPSConnection object at 0x00000103B45BB3A0>: Failed to establish a new connection: [Errno 11001] getaddrinfo failed'))
|ERROR|2022-08-22 23:50:00,662|Connection error: HTTPSConnectionPool(host='api-demo.fxcm.com', port=443): Max retries exceeded with url: /socket.io/?access_token=97d9d09d13219a0032426fdcf1fe18e656f91a05&agent=pythonquants&wait_for_connection=False&transport=polling&EIO=4&t=1661192400.6380076 (Caused by NewConnectionError('<urllib3.connection.HTTPSConnection object at 0x00000103B45BB9A0>: Failed to establish a new connection: [Errno 11001] getaddrinfo failed'))
|ERROR|2022-08-22 23:50:05,880|Connection error: HTTPSConnectionPool(host='api-demo.fxcm.com', port=443): Max retries exceeded with url: /socket.io/?access_token=97d9d09d13219a0032426fdcf1fe18e656f91a05&agent=pythonquants&wait_for_connection=False&transport=polling&EIO=4&t=1661192405.872976 (Caused by NewConnectionError('<urllib3.connection.HTTPSConnection object at 0x00000103B45BB3A0>: Failed to establish a new connection: [Errno 11001] getaddrinfo failed'))
|ERROR|2022-08-22 23:50:10,841|Connection error: HTTPSConnectionPool(host='api-demo.fxcm.com', port=443): Max retries exceeded with url: /socket.io/?access_token=97d9d09d13219a0032426fdcf1fe18e656f91a05&agent=pythonquants&wait_for_connection=False&transport=polling&EIO=4&t=1661192410.8338745 (Caused by NewConnectionError('<urllib3.connection.HTTPSConnection object at 0x00000103B45BB9A0>: Failed to establish a new connection: [Errno 11001] getaddrinfo failed'))
|ERROR|2022-08-22 23:50:16,130|Connection error: HTTPSConnectionPool(host='api-demo.fxcm.com', port=443): Max retries exceeded with url: /socket.io/?access_token=97d9d09d13219a0032426fdcf1fe18e656f91a05&agent=pythonquants&wait_for_connection=False&transport=polling&EIO=4&t=1661192416.1273189 (Caused by NewConnectionError('<urllib3.connection.HTTPSConnection object at 0x00000103B45BB3A0>: Failed to establish a new connection: [Errno 11001] getaddrinfo failed'))
|ERROR|2022-08-22 23:50:21,006|Connection error: HTTPSConnectionPool(host='api-demo.fxcm.com', port=443): Max retries exceeded with url: /socket.io/?access_token=97d9d09d13219a0032426fdcf1fe18e656f91a05&agent=pythonquants&wait_for_connection=False&transport=polling&EIO=4&t=1661192420.9980307 (Caused by NewConnectionError('<urllib3.connection.HTTPSConnection object at 0x00000103B45BB9A0>: Failed to establish a new connection: [Errno 11001] getaddrinfo failed'))
|ERROR|2022-08-22 23:50:26,002|Connection error: HTTPSConnectionPool(host='api-demo.fxcm.com', port=443): Max retries exceeded with url: /socket.io/?access_token=97d9d09d13219a0032426fdcf1fe18e656f91a05&agent=pythonquants&wait_for_connection=False&transport=polling&EIO=4&t=1661192425.9947743 (Caused by NewConnectionError('<urllib3.connection.HTTPSConnection object at 0x00000103B45BB3A0>: Failed to establish a new connection: [Errno 11001] getaddrinfo failed'))
|ERROR|2022-08-22 23:50:30,791|Connection error: HTTPSConnectionPool(host='api-demo.fxcm.com', port=443): Max retries exceeded with url: /socket.io/?access_token=97d9d09d13219a0032426fdcf1fe18e656f91a05&agent=pythonquants&wait_for_connection=False&transport=polling&EIO=4&t=1661192430.7775605 (Caused by NewConnectionError('<urllib3.connection.HTTPSConnection object at 0x00000103B45BB9A0>: Failed to establish a new connection: [Errno 11001] getaddrinfo failed'))
|ERROR|2022-08-22 23:50:36,029|Connection error: HTTPSConnectionPool(host='api-demo.fxcm.com', port=443): Max retries exceeded with url: /socket.io/?access_token=97d9d09d13219a0032426fdcf1fe18e656f91a05&agent=pythonquants&wait_for_connection=False&transport=polling&EIO=4&t=1661192436.0229445 (Caused by NewConnectionError('<urllib3.connection.HTTPSConnection object at 0x00000103B45BB3A0>: Failed to establish a new connection: [Errno 11001] getaddrinfo failed'))
|ERROR|2022-08-22 23:50:40,857|Connection error: HTTPSConnectionPool(host='api-demo.fxcm.com', port=443): Max retries exceeded with url: /socket.io/?access_token=97d9d09d13219a0032426fdcf1fe18e656f91a05&agent=pythonquants&wait_for_connection=False&transport=polling&EIO=4&t=1661192440.849659 (Caused by NewConnectionError('<urllib3.connection.HTTPSConnection object at 0x00000103B45BB9A0>: Failed to establish a new connection: [Errno 11001] getaddrinfo failed'))
|ERROR|2022-08-22 23:50:45,760|Connection error: HTTPSConnectionPool(host='api-demo.fxcm.com', port=443): Max retries exceeded with url: /socket.io/?access_token=97d9d09d13219a0032426fdcf1fe18e656f91a05&agent=pythonquants&wait_for_connection=False&transport=polling&EIO=4&t=1661192445.7548258 (Caused by NewConnectionError('<urllib3.connection.HTTPSConnection object at 0x00000103B45BB3A0>: Failed to establish a new connection: [Errno 11001] getaddrinfo failed'))
|ERROR|2022-08-22 23:50:50,509|Connection error: HTTPSConnectionPool(host='api-demo.fxcm.com', port=443): Max retries exceeded with url: /socket.io/?access_token=97d9d09d13219a0032426fdcf1fe18e656f91a05&agent=pythonquants&wait_for_connection=False&transport=polling&EIO=4&t=1661192450.5025978 (Caused by NewConnectionError('<urllib3.connection.HTTPSConnection object at 0x00000103B45BB9A0>: Failed to establish a new connection: [Errno 11001] getaddrinfo failed'))
|ERROR|2022-08-22 23:50:55,376|Connection error: HTTPSConnectionPool(host='api-demo.fxcm.com', port=443): Max retries exceeded with url: /socket.io/?access_token=97d9d09d13219a0032426fdcf1fe18e656f91a05&agent=pythonquants&wait_for_connection=False&transport=polling&EIO=4&t=1661192455.3723884 (Caused by NewConnectionError('<urllib3.connection.HTTPSConnection object at 0x00000103B45BB3A0>: Failed to establish a new connection: [Errno 11001] getaddrinfo failed'))
|ERROR|2022-08-22 23:51:00,689|Connection error: HTTPSConnectionPool(host='api-demo.fxcm.com', port=443): Max retries exceeded with url: /socket.io/?access_token=97d9d09d13219a0032426fdcf1fe18e656f91a05&agent=pythonquants&wait_for_connection=False&transport=polling&EIO=4&t=1661192460.678171 (Caused by NewConnectionError('<urllib3.connection.HTTPSConnection object at 0x00000103B45BB9A0>: Failed to establish a new connection: [Errno 11001] getaddrinfo failed'))
|ERROR|2022-08-22 23:51:06,118|Connection error: HTTPSConnectionPool(host='api-demo.fxcm.com', port=443): Max retries exceeded with url: /socket.io/?access_token=97d9d09d13219a0032426fdcf1fe18e656f91a05&agent=pythonquants&wait_for_connection=False&transport=polling&EIO=4&t=1661192466.1118495 (Caused by NewConnectionError('<urllib3.connection.HTTPSConnection object at 0x00000103B45BB3A0>: Failed to establish a new connection: [Errno 11001] getaddrinfo failed'))
|ERROR|2022-08-22 23:51:10,811|Connection error: HTTPSConnectionPool(host='api-demo.fxcm.com', port=443): Max retries exceeded with url: /socket.io/?access_token=97d9d09d13219a0032426fdcf1fe18e656f91a05&agent=pythonquants&wait_for_connection=False&transport=polling&EIO=4&t=1661192470.804805 (Caused by NewConnectionError('<urllib3.connection.HTTPSConnection object at 0x00000103B45BB9A0>: Failed to establish a new connection: [Errno 11001] getaddrinfo failed'))
|ERROR|2022-08-22 23:51:15,874|Connection error: HTTPSConnectionPool(host='api-demo.fxcm.com', port=443): Max retries exceeded with url: /socket.io/?access_token=97d9d09d13219a0032426fdcf1fe18e656f91a05&agent=pythonquants&wait_for_connection=False&transport=polling&EIO=4&t=1661192475.8671286 (Caused by NewConnectionError('<urllib3.connection.HTTPSConnection object at 0x00000103B45BB3A0>: Failed to establish a new connection: [Errno 11001] getaddrinfo failed'))
|ERROR|2022-08-22 23:51:21,159|Connection error: HTTPSConnectionPool(host='api-demo.fxcm.com', port=443): Max retries exceeded with url: /socket.io/?access_token=97d9d09d13219a0032426fdcf1fe18e656f91a05&agent=pythonquants&wait_for_connection=False&transport=polling&EIO=4&t=1661192481.152315 (Caused by NewConnectionError('<urllib3.connection.HTTPSConnection object at 0x00000103B45BB9A0>: Failed to establish a new connection: [Errno 11001] getaddrinfo failed'))
|ERROR|2022-08-22 23:51:26,154|Connection error: HTTPSConnectionPool(host='api-demo.fxcm.com', port=443): Max retries exceeded with url: /socket.io/?access_token=97d9d09d13219a0032426fdcf1fe18e656f91a05&agent=pythonquants&wait_for_connection=False&transport=polling&EIO=4&t=1661192486.147206 (Caused by NewConnectionError('<urllib3.connection.HTTPSConnection object at 0x00000103B45BB3A0>: Failed to establish a new connection: [Errno 11001] getaddrinfo failed'))
|ERROR|2022-08-22 23:51:31,146|Connection error: HTTPSConnectionPool(host='api-demo.fxcm.com', port=443): Max retries exceeded with url: /socket.io/?access_token=97d9d09d13219a0032426fdcf1fe18e656f91a05&agent=pythonquants&wait_for_connection=False&transport=polling&EIO=4&t=1661192491.1431806 (Caused by NewConnectionError('<urllib3.connection.HTTPSConnection object at 0x00000103B45BB9A0>: Failed to establish a new connection: [Errno 11001] getaddrinfo failed'))
|ERROR|2022-08-22 23:51:36,426|Connection error: HTTPSConnectionPool(host='api-demo.fxcm.com', port=443): Max retries exceeded with url: /socket.io/?access_token=97d9d09d13219a0032426fdcf1fe18e656f91a05&agent=pythonquants&wait_for_connection=False&transport=polling&EIO=4&t=1661192496.4237978 (Caused by NewConnectionError('<urllib3.connection.HTTPSConnection object at 0x00000103B45BB3A0>: Failed to establish a new connection: [Errno 11001] getaddrinfo failed'))
|ERROR|2022-08-22 23:51:41,212|Connection error: HTTPSConnectionPool(host='api-demo.fxcm.com', port=443): Max retries exceeded with url: /socket.io/?access_token=97d9d09d13219a0032426fdcf1fe18e656f91a05&agent=pythonquants&wait_for_connection=False&transport=polling&EIO=4&t=1661192501.2095022 (Caused by NewConnectionError('<urllib3.connection.HTTPSConnection object at 0x00000103B45BB9A0>: Failed to establish a new connection: [Errno 11001] getaddrinfo failed'))
|ERROR|2022-08-22 23:51:46,039|Connection error: HTTPSConnectionPool(host='api-demo.fxcm.com', port=443): Max retries exceeded with url: /socket.io/?access_token=97d9d09d13219a0032426fdcf1fe18e656f91a05&agent=pythonquants&wait_for_connection=False&transport=polling&EIO=4&t=1661192506.0312252 (Caused by NewConnectionError('<urllib3.connection.HTTPSConnection object at 0x00000103B45BB3A0>: Failed to establish a new connection: [Errno 11001] getaddrinfo failed'))
|ERROR|2022-08-22 23:51:51,339|Connection error: HTTPSConnectionPool(host='api-demo.fxcm.com', port=443): Max retries exceeded with url: /socket.io/?access_token=97d9d09d13219a0032426fdcf1fe18e656f91a05&agent=pythonquants&wait_for_connection=False&transport=polling&EIO=4&t=1661192511.333579 (Caused by NewConnectionError('<urllib3.connection.HTTPSConnection object at 0x00000103B45BB9A0>: Failed to establish a new connection: [Errno 11001] getaddrinfo failed'))
|ERROR|2022-08-22 23:51:56,653|Connection error: HTTPSConnectionPool(host='api-demo.fxcm.com', port=443): Max retries exceeded with url: /socket.io/?access_token=97d9d09d13219a0032426fdcf1fe18e656f91a05&agent=pythonquants&wait_for_connection=False&transport=polling&EIO=4&t=1661192516.650155 (Caused by NewConnectionError('<urllib3.connection.HTTPSConnection object at 0x00000103B45BB3A0>: Failed to establish a new connection: [Errno 11001] getaddrinfo failed'))
|ERROR|2022-08-22 23:52:01,707|Connection error: HTTPSConnectionPool(host='api-demo.fxcm.com', port=443): Max retries exceeded with url: /socket.io/?access_token=97d9d09d13219a0032426fdcf1fe18e656f91a05&agent=pythonquants&wait_for_connection=False&transport=polling&EIO=4&t=1661192521.7019162 (Caused by NewConnectionError('<urllib3.connection.HTTPSConnection object at 0x00000103B45BB9A0>: Failed to establish a new connection: [Errno 11001] getaddrinfo failed'))
|ERROR|2022-08-22 23:52:06,282|Connection error: HTTPSConnectionPool(host='api-demo.fxcm.com', port=443): Max retries exceeded with url: /socket.io/?access_token=97d9d09d13219a0032426fdcf1fe18e656f91a05&agent=pythonquants&wait_for_connection=False&transport=polling&EIO=4&t=1661192526.2783227 (Caused by NewConnectionError('<urllib3.connection.HTTPSConnection object at 0x00000103B45BB3A0>: Failed to establish a new connection: [Errno 11001] getaddrinfo failed'))
|ERROR|2022-08-22 23:52:10,848|Connection error: HTTPSConnectionPool(host='api-demo.fxcm.com', port=443): Max retries exceeded with url: /socket.io/?access_token=97d9d09d13219a0032426fdcf1fe18e656f91a05&agent=pythonquants&wait_for_connection=False&transport=polling&EIO=4&t=1661192530.8401496 (Caused by NewConnectionError('<urllib3.connection.HTTPSConnection object at 0x00000103B45BB9A0>: Failed to establish a new connection: [Errno 11001] getaddrinfo failed'))
|ERROR|2022-08-22 23:52:16,255|Connection error: HTTPSConnectionPool(host='api-demo.fxcm.com', port=443): Max retries exceeded with url: /socket.io/?access_token=97d9d09d13219a0032426fdcf1fe18e656f91a05&agent=pythonquants&wait_for_connection=False&transport=polling&EIO=4&t=1661192536.2340248 (Caused by NewConnectionError('<urllib3.connection.HTTPSConnection object at 0x00000103B45BB3A0>: Failed to establish a new connection: [Errno 11001] getaddrinfo failed'))
|ERROR|2022-08-22 23:52:21,116|Connection error: HTTPSConnectionPool(host='api-demo.fxcm.com', port=443): Max retries exceeded with url: /socket.io/?access_token=97d9d09d13219a0032426fdcf1fe18e656f91a05&agent=pythonquants&wait_for_connection=False&transport=polling&EIO=4&t=1661192541.111962 (Caused by NewConnectionError('<urllib3.connection.HTTPSConnection object at 0x00000103B45BB9A0>: Failed to establish a new connection: [Errno 11001] getaddrinfo failed'))
|ERROR|2022-08-22 23:52:26,421|Connection error: HTTPSConnectionPool(host='api-demo.fxcm.com', port=443): Max retries exceeded with url: /socket.io/?access_token=97d9d09d13219a0032426fdcf1fe18e656f91a05&agent=pythonquants&wait_for_connection=False&transport=polling&EIO=4&t=1661192546.413369 (Caused by NewConnectionError('<urllib3.connection.HTTPSConnection object at 0x00000103B45BB3A0>: Failed to establish a new connection: [Errno 11001] getaddrinfo failed'))
|ERROR|2022-08-22 23:52:31,338|Connection error: HTTPSConnectionPool(host='api-demo.fxcm.com', port=443): Max retries exceeded with url: /socket.io/?access_token=97d9d09d13219a0032426fdcf1fe18e656f91a05&agent=pythonquants&wait_for_connection=False&transport=polling&EIO=4&t=1661192551.3175201 (Caused by NewConnectionError('<urllib3.connection.HTTPSConnection object at 0x00000103B45BB9A0>: Failed to establish a new connection: [Errno 11001] getaddrinfo failed'))
|ERROR|2022-08-22 23:52:36,412|Connection error: HTTPSConnectionPool(host='api-demo.fxcm.com', port=443): Max retries exceeded with url: /socket.io/?access_token=97d9d09d13219a0032426fdcf1fe18e656f91a05&agent=pythonquants&wait_for_connection=False&transport=polling&EIO=4&t=1661192556.4053636 (Caused by NewConnectionError('<urllib3.connection.HTTPSConnection object at 0x00000103B45BB3A0>: Failed to establish a new connection: [Errno 11001] getaddrinfo failed'))
|ERROR|2022-08-22 23:52:41,362|Connection error: HTTPSConnectionPool(host='api-demo.fxcm.com', port=443): Max retries exceeded with url: /socket.io/?access_token=97d9d09d13219a0032426fdcf1fe18e656f91a05&agent=pythonquants&wait_for_connection=False&transport=polling&EIO=4&t=1661192561.355314 (Caused by NewConnectionError('<urllib3.connection.HTTPSConnection object at 0x00000103B45BB9A0>: Failed to establish a new connection: [Errno 11001] getaddrinfo failed'))
|ERROR|2022-08-22 23:52:46,726|Connection error: HTTPSConnectionPool(host='api-demo.fxcm.com', port=443): Max retries exceeded with url: /socket.io/?access_token=97d9d09d13219a0032426fdcf1fe18e656f91a05&agent=pythonquants&wait_for_connection=False&transport=polling&EIO=4&t=1661192566.704468 (Caused by NewConnectionError('<urllib3.connection.HTTPSConnection object at 0x00000103B45BB3A0>: Failed to establish a new connection: [Errno 11001] getaddrinfo failed'))
|ERROR|2022-08-22 23:52:52,114|Connection error: HTTPSConnectionPool(host='api-demo.fxcm.com', port=443): Max retries exceeded with url: /socket.io/?access_token=97d9d09d13219a0032426fdcf1fe18e656f91a05&agent=pythonquants&wait_for_connection=False&transport=polling&EIO=4&t=1661192572.107507 (Caused by NewConnectionError('<urllib3.connection.HTTPSConnection object at 0x00000103B45BB9A0>: Failed to establish a new connection: [Errno 11001] getaddrinfo failed'))
|ERROR|2022-08-22 23:52:56,668|Connection error: HTTPSConnectionPool(host='api-demo.fxcm.com', port=443): Max retries exceeded with url: /socket.io/?access_token=97d9d09d13219a0032426fdcf1fe18e656f91a05&agent=pythonquants&wait_for_connection=False&transport=polling&EIO=4&t=1661192576.665226 (Caused by NewConnectionError('<urllib3.connection.HTTPSConnection object at 0x00000103B45BB3A0>: Failed to establish a new connection: [Errno 11001] getaddrinfo failed'))
|ERROR|2022-08-22 23:53:01,384|Connection error: HTTPSConnectionPool(host='api-demo.fxcm.com', port=443): Max retries exceeded with url: /socket.io/?access_token=97d9d09d13219a0032426fdcf1fe18e656f91a05&agent=pythonquants&wait_for_connection=False&transport=polling&EIO=4&t=1661192581.3627474 (Caused by NewConnectionError('<urllib3.connection.HTTPSConnection object at 0x00000103B45BB9A0>: Failed to establish a new connection: [Errno 11001] getaddrinfo failed'))
|ERROR|2022-08-22 23:53:06,080|Connection error: HTTPSConnectionPool(host='api-demo.fxcm.com', port=443): Max retries exceeded with url: /socket.io/?access_token=97d9d09d13219a0032426fdcf1fe18e656f91a05&agent=pythonquants&wait_for_connection=False&transport=polling&EIO=4&t=1661192586.0731988 (Caused by NewConnectionError('<urllib3.connection.HTTPSConnection object at 0x00000103B45BB3A0>: Failed to establish a new connection: [Errno 11001] getaddrinfo failed'))
|ERROR|2022-08-22 23:53:10,751|Connection error: HTTPSConnectionPool(host='api-demo.fxcm.com', port=443): Max retries exceeded with url: /socket.io/?access_token=97d9d09d13219a0032426fdcf1fe18e656f91a05&agent=pythonquants&wait_for_connection=False&transport=polling&EIO=4&t=1661192590.7449193 (Caused by NewConnectionError('<urllib3.connection.HTTPSConnection object at 0x00000103B45BB9A0>: Failed to establish a new connection: [Errno 11001] getaddrinfo failed'))
|ERROR|2022-08-22 23:53:15,788|Connection error: HTTPSConnectionPool(host='api-demo.fxcm.com', port=443): Max retries exceeded with url: /socket.io/?access_token=97d9d09d13219a0032426fdcf1fe18e656f91a05&agent=pythonquants&wait_for_connection=False&transport=polling&EIO=4&t=1661192595.781441 (Caused by NewConnectionError('<urllib3.connection.HTTPSConnection object at 0x00000103B45BB3A0>: Failed to establish a new connection: [Errno 11001] getaddrinfo failed'))
|ERROR|2022-08-22 23:53:20,323|Connection error: HTTPSConnectionPool(host='api-demo.fxcm.com', port=443): Max retries exceeded with url: /socket.io/?access_token=97d9d09d13219a0032426fdcf1fe18e656f91a05&agent=pythonquants&wait_for_connection=False&transport=polling&EIO=4&t=1661192600.3174057 (Caused by NewConnectionError('<urllib3.connection.HTTPSConnection object at 0x00000103B45BB9A0>: Failed to establish a new connection: [Errno 11001] getaddrinfo failed'))
|ERROR|2022-08-22 23:53:25,347|Connection error: HTTPSConnectionPool(host='api-demo.fxcm.com', port=443): Max retries exceeded with url: /socket.io/?access_token=97d9d09d13219a0032426fdcf1fe18e656f91a05&agent=pythonquants&wait_for_connection=False&transport=polling&EIO=4&t=1661192605.3430662 (Caused by NewConnectionError('<urllib3.connection.HTTPSConnection object at 0x00000103B45BB3A0>: Failed to establish a new connection: [Errno 11001] getaddrinfo failed'))
|ERROR|2022-08-22 23:53:30,142|Connection error: HTTPSConnectionPool(host='api-demo.fxcm.com', port=443): Max retries exceeded with url: /socket.io/?access_token=97d9d09d13219a0032426fdcf1fe18e656f91a05&agent=pythonquants&wait_for_connection=False&transport=polling&EIO=4&t=1661192610.135482 (Caused by NewConnectionError('<urllib3.connection.HTTPSConnection object at 0x00000103B45BB9A0>: Failed to establish a new connection: [Errno 11001] getaddrinfo failed'))
|ERROR|2022-08-22 23:53:35,533|Connection error: HTTPSConnectionPool(host='api-demo.fxcm.com', port=443): Max retries exceeded with url: /socket.io/?access_token=97d9d09d13219a0032426fdcf1fe18e656f91a05&agent=pythonquants&wait_for_connection=False&transport=polling&EIO=4&t=1661192615.5265927 (Caused by NewConnectionError('<urllib3.connection.HTTPSConnection object at 0x00000103B45BB3A0>: Failed to establish a new connection: [Errno 11001] getaddrinfo failed'))
|ERROR|2022-08-22 23:53:40,768|Connection error: HTTPSConnectionPool(host='api-demo.fxcm.com', port=443): Max retries exceeded with url: /socket.io/?access_token=97d9d09d13219a0032426fdcf1fe18e656f91a05&agent=pythonquants&wait_for_connection=False&transport=polling&EIO=4&t=1661192620.7591465 (Caused by NewConnectionError('<urllib3.connection.HTTPSConnection object at 0x00000103B45BB9A0>: Failed to establish a new connection: [Errno 11001] getaddrinfo failed'))
|ERROR|2022-08-22 23:53:45,411|Connection error: HTTPSConnectionPool(host='api-demo.fxcm.com', port=443): Max retries exceeded with url: /socket.io/?access_token=97d9d09d13219a0032426fdcf1fe18e656f91a05&agent=pythonquants&wait_for_connection=False&transport=polling&EIO=4&t=1661192625.404083 (Caused by NewConnectionError('<urllib3.connection.HTTPSConnection object at 0x00000103B45BB3A0>: Failed to establish a new connection: [Errno 11001] getaddrinfo failed'))
|ERROR|2022-08-22 23:53:50,884|Connection error: HTTPSConnectionPool(host='api-demo.fxcm.com', port=443): Max retries exceeded with url: /socket.io/?access_token=97d9d09d13219a0032426fdcf1fe18e656f91a05&agent=pythonquants&wait_for_connection=False&transport=polling&EIO=4&t=1661192630.8764489 (Caused by NewConnectionError('<urllib3.connection.HTTPSConnection object at 0x00000103B45BB9A0>: Failed to establish a new connection: [Errno 11001] getaddrinfo failed'))
|ERROR|2022-08-22 23:53:55,964|Connection error: HTTPSConnectionPool(host='api-demo.fxcm.com', port=443): Max retries exceeded with url: /socket.io/?access_token=97d9d09d13219a0032426fdcf1fe18e656f91a05&agent=pythonquants&wait_for_connection=False&transport=polling&EIO=4&t=1661192635.9566934 (Caused by NewConnectionError('<urllib3.connection.HTTPSConnection object at 0x00000103B45BB3A0>: Failed to establish a new connection: [Errno 11001] getaddrinfo failed'))
|ERROR|2022-08-22 23:54:00,618|Connection error: HTTPSConnectionPool(host='api-demo.fxcm.com', port=443): Max retries exceeded with url: /socket.io/?access_token=97d9d09d13219a0032426fdcf1fe18e656f91a05&agent=pythonquants&wait_for_connection=False&transport=polling&EIO=4&t=1661192640.6116998 (Caused by NewConnectionError('<urllib3.connection.HTTPSConnection object at 0x00000103B45BB9A0>: Failed to establish a new connection: [Errno 11001] getaddrinfo failed'))
|ERROR|2022-08-22 23:54:05,226|Connection error: HTTPSConnectionPool(host='api-demo.fxcm.com', port=443): Max retries exceeded with url: /socket.io/?access_token=97d9d09d13219a0032426fdcf1fe18e656f91a05&agent=pythonquants&wait_for_connection=False&transport=polling&EIO=4&t=1661192645.2193358 (Caused by NewConnectionError('<urllib3.connection.HTTPSConnection object at 0x00000103B45BB3A0>: Failed to establish a new connection: [Errno 11001] getaddrinfo failed'))
|ERROR|2022-08-22 23:54:10,483|Connection error: HTTPSConnectionPool(host='api-demo.fxcm.com', port=443): Max retries exceeded with url: /socket.io/?access_token=97d9d09d13219a0032426fdcf1fe18e656f91a05&agent=pythonquants&wait_for_connection=False&transport=polling&EIO=4&t=1661192650.4774518 (Caused by NewConnectionError('<urllib3.connection.HTTPSConnection object at 0x00000103B45BB9A0>: Failed to establish a new connection: [Errno 11001] getaddrinfo failed'))
|ERROR|2022-08-22 23:54:15,238|Connection error: HTTPSConnectionPool(host='api-demo.fxcm.com', port=443): Max retries exceeded with url: /socket.io/?access_token=97d9d09d13219a0032426fdcf1fe18e656f91a05&agent=pythonquants&wait_for_connection=False&transport=polling&EIO=4&t=1661192655.2316673 (Caused by NewConnectionError('<urllib3.connection.HTTPSConnection object at 0x00000103B45BB3A0>: Failed to establish a new connection: [Errno 11001] getaddrinfo failed'))
|ERROR|2022-08-22 23:54:20,565|Connection error: HTTPSConnectionPool(host='api-demo.fxcm.com', port=443): Max retries exceeded with url: /socket.io/?access_token=97d9d09d13219a0032426fdcf1fe18e656f91a05&agent=pythonquants&wait_for_connection=False&transport=polling&EIO=4&t=1661192660.5484946 (Caused by NewConnectionError('<urllib3.connection.HTTPSConnection object at 0x00000103B45BB9A0>: Failed to establish a new connection: [Errno 11001] getaddrinfo failed'))
|ERROR|2022-08-22 23:54:25,752|Connection error: HTTPSConnectionPool(host='api-demo.fxcm.com', port=443): Max retries exceeded with url: /socket.io/?access_token=97d9d09d13219a0032426fdcf1fe18e656f91a05&agent=pythonquants&wait_for_connection=False&transport=polling&EIO=4&t=1661192665.7465029 (Caused by NewConnectionError('<urllib3.connection.HTTPSConnection object at 0x00000103B45BB3A0>: Failed to establish a new connection: [Errno 11001] getaddrinfo failed'))
|ERROR|2022-08-22 23:54:30,588|Connection error: HTTPSConnectionPool(host='api-demo.fxcm.com', port=443): Max retries exceeded with url: /socket.io/?access_token=97d9d09d13219a0032426fdcf1fe18e656f91a05&agent=pythonquants&wait_for_connection=False&transport=polling&EIO=4&t=1661192670.581337 (Caused by NewConnectionError('<urllib3.connection.HTTPSConnection object at 0x00000103B45BB9A0>: Failed to establish a new connection: [Errno 11001] getaddrinfo failed'))
|ERROR|2022-08-22 23:54:35,265|Connection error: HTTPSConnectionPool(host='api-demo.fxcm.com', port=443): Max retries exceeded with url: /socket.io/?access_token=97d9d09d13219a0032426fdcf1fe18e656f91a05&agent=pythonquants&wait_for_connection=False&transport=polling&EIO=4&t=1661192675.2506733 (Caused by NewConnectionError('<urllib3.connection.HTTPSConnection object at 0x00000103B45BB3A0>: Failed to establish a new connection: [Errno 11001] getaddrinfo failed'))
|ERROR|2022-08-22 23:54:40,225|Connection error: HTTPSConnectionPool(host='api-demo.fxcm.com', port=443): Max retries exceeded with url: /socket.io/?access_token=97d9d09d13219a0032426fdcf1fe18e656f91a05&agent=pythonquants&wait_for_connection=False&transport=polling&EIO=4&t=1661192680.2188468 (Caused by NewConnectionError('<urllib3.connection.HTTPSConnection object at 0x00000103B45BB9A0>: Failed to establish a new connection: [Errno 11001] getaddrinfo failed'))
|ERROR|2022-08-22 23:54:45,206|Connection error: HTTPSConnectionPool(host='api-demo.fxcm.com', port=443): Max retries exceeded with url: /socket.io/?access_token=97d9d09d13219a0032426fdcf1fe18e656f91a05&agent=pythonquants&wait_for_connection=False&transport=polling&EIO=4&t=1661192685.2008538 (Caused by NewConnectionError('<urllib3.connection.HTTPSConnection object at 0x00000103B45BB3A0>: Failed to establish a new connection: [Errno 11001] getaddrinfo failed'))
|ERROR|2022-08-22 23:54:50,132|Connection error: HTTPSConnectionPool(host='api-demo.fxcm.com', port=443): Max retries exceeded with url: /socket.io/?access_token=97d9d09d13219a0032426fdcf1fe18e656f91a05&agent=pythonquants&wait_for_connection=False&transport=polling&EIO=4&t=1661192690.1196766 (Caused by NewConnectionError('<urllib3.connection.HTTPSConnection object at 0x00000103B45BB9A0>: Failed to establish a new connection: [Errno 11001] getaddrinfo failed'))
|ERROR|2022-08-22 23:54:55,080|Connection error: HTTPSConnectionPool(host='api-demo.fxcm.com', port=443): Max retries exceeded with url: /socket.io/?access_token=97d9d09d13219a0032426fdcf1fe18e656f91a05&agent=pythonquants&wait_for_connection=False&transport=polling&EIO=4&t=1661192695.0783212 (Caused by NewConnectionError('<urllib3.connection.HTTPSConnection object at 0x00000103B45BB3A0>: Failed to establish a new connection: [Errno 11001] getaddrinfo failed'))
|ERROR|2022-08-23 00:07:45,206|Connection error: HTTPSConnectionPool(host='api-demo.fxcm.com', port=443): Read timed out. (read timeout=5)
|ERROR|2022-08-23 00:31:21,771|Connection error: HTTPSConnectionPool(host='api-demo.fxcm.com', port=443): Read timed out. (read timeout=5)
|ERROR|2022-08-23 00:31:33,820|Connection error: HTTPSConnectionPool(host='api-demo.fxcm.com', port=443): Read timed out. (read timeout=5)
|ERROR|2022-08-23 05:06:32,922|Connection error: HTTPSConnectionPool(host='api-demo.fxcm.com', port=443): Max retries exceeded with url: /socket.io/?access_token=97d9d09d13219a0032426fdcf1fe18e656f91a05&agent=pythonquants&wait_for_connection=False&transport=polling&EIO=4&t=1661211392.903236 (Caused by NewConnectionError('<urllib3.connection.HTTPSConnection object at 0x00000103B4616670>: Failed to establish a new connection: [Errno 11001] getaddrinfo failed'))
|ERROR|2022-08-23 10:45:39,191|Connection error: HTTPSConnectionPool(host='api-demo.fxcm.com', port=443): Max retries exceeded with url: /socket.io/?access_token=97d9d09d13219a0032426fdcf1fe18e656f91a05&agent=pythonquants&wait_for_connection=False&transport=polling&EIO=4&t=1661231739.111491 (Caused by NewConnectionError('<urllib3.connection.HTTPSConnection object at 0x00000103B4616820>: Failed to establish a new connection: [Errno 11001] getaddrinfo failed'))
|ERROR|2022-08-23 10:45:43,081|Connection error: HTTPSConnectionPool(host='api-demo.fxcm.com', port=443): Max retries exceeded with url: /socket.io/?access_token=97d9d09d13219a0032426fdcf1fe18e656f91a05&agent=pythonquants&wait_for_connection=False&transport=polling&EIO=4&t=1661231742.9198213 (Caused by NewConnectionError('<urllib3.connection.HTTPSConnection object at 0x00000103B4616D90>: Failed to establish a new connection: [Errno 11001] getaddrinfo failed'))
|ERROR|2022-08-23 10:45:47,981|Connection error: HTTPSConnectionPool(host='api-demo.fxcm.com', port=443): Max retries exceeded with url: /socket.io/?access_token=97d9d09d13219a0032426fdcf1fe18e656f91a05&agent=pythonquants&wait_for_connection=False&transport=polling&EIO=4&t=1661231747.9779136 (Caused by NewConnectionError('<urllib3.connection.HTTPSConnection object at 0x00000103B4616670>: Failed to establish a new connection: [Errno 11001] getaddrinfo failed'))
|ERROR|2022-08-23 10:45:52,640|Connection error: HTTPSConnectionPool(host='api-demo.fxcm.com', port=443): Max retries exceeded with url: /socket.io/?access_token=97d9d09d13219a0032426fdcf1fe18e656f91a05&agent=pythonquants&wait_for_connection=False&transport=polling&EIO=4&t=1661231752.638196 (Caused by NewConnectionError('<urllib3.connection.HTTPSConnection object at 0x00000103B46168E0>: Failed to establish a new connection: [Errno 11001] getaddrinfo failed'))
|ERROR|2022-08-23 10:45:57,428|Connection error: HTTPSConnectionPool(host='api-demo.fxcm.com', port=443): Max retries exceeded with url: /socket.io/?access_token=97d9d09d13219a0032426fdcf1fe18e656f91a05&agent=pythonquants&wait_for_connection=False&transport=polling&EIO=4&t=1661231757.4252362 (Caused by NewConnectionError('<urllib3.connection.HTTPSConnection object at 0x00000103B4616FA0>: Failed to establish a new connection: [Errno 11001] getaddrinfo failed'))
|ERROR|2022-08-23 10:46:02,594|Connection error: HTTPSConnectionPool(host='api-demo.fxcm.com', port=443): Max retries exceeded with url: /socket.io/?access_token=97d9d09d13219a0032426fdcf1fe18e656f91a05&agent=pythonquants&wait_for_connection=False&transport=polling&EIO=4&t=1661231762.5929718 (Caused by NewConnectionError('<urllib3.connection.HTTPSConnection object at 0x00000103B4616760>: Failed to establish a new connection: [Errno 11001] getaddrinfo failed'))
|ERROR|2022-08-23 10:46:07,559|Connection error: HTTPSConnectionPool(host='api-demo.fxcm.com', port=443): Max retries exceeded with url: /socket.io/?access_token=97d9d09d13219a0032426fdcf1fe18e656f91a05&agent=pythonquants&wait_for_connection=False&transport=polling&EIO=4&t=1661231767.5533974 (Caused by NewConnectionError('<urllib3.connection.HTTPSConnection object at 0x00000103B4616040>: Failed to establish a new connection: [Errno 11001] getaddrinfo failed'))
|ERROR|2022-08-23 10:46:49,842|Connection error: HTTPSConnectionPool(host='api-demo.fxcm.com', port=443): Max retries exceeded with url: /socket.io/?access_token=97d9d09d13219a0032426fdcf1fe18e656f91a05&agent=pythonquants&wait_for_connection=False&transport=polling&EIO=4&t=1661231809.7661986 (Caused by NewConnectionError('<urllib3.connection.HTTPSConnection object at 0x00000103B4616820>: Failed to establish a new connection: [Errno 11001] getaddrinfo failed'))
|ERROR|2022-08-23 10:46:54,662|Connection error: HTTPSConnectionPool(host='api-demo.fxcm.com', port=443): Max retries exceeded with url: /socket.io/?access_token=97d9d09d13219a0032426fdcf1fe18e656f91a05&agent=pythonquants&wait_for_connection=False&transport=polling&EIO=4&t=1661231814.6595416 (Caused by NewConnectionError('<urllib3.connection.HTTPSConnection object at 0x00000103B4616AC0>: Failed to establish a new connection: [Errno 11001] getaddrinfo failed'))
|ERROR|2022-08-23 15:58:21,367|packet queue is empty, aborting
|ERROR|2022-08-23 16:40:05,047|packet queue is empty, aborting
|ERROR|2022-08-23 16:40:48,055|Connection error: HTTPSConnectionPool(host='api-demo.fxcm.com', port=443): Read timed out. (read timeout=5)
|ERROR|2022-08-23 16:40:50,043|Connection error: HTTPSConnectionPool(host='api-demo.fxcm.com', port=443): Max retries exceeded with url: /socket.io/?access_token=97d9d09d13219a0032426fdcf1fe18e656f91a05&agent=pythonquants&wait_for_connection=False&transport=polling&EIO=4&t=1661253050.0109344 (Caused by NewConnectionError('<urllib3.connection.HTTPSConnection object at 0x00000103B4660220>: Failed to establish a new connection: [Errno 11001] getaddrinfo failed'))
|ERROR|2022-08-23 16:40:54,252|Connection error: HTTPSConnectionPool(host='api-demo.fxcm.com', port=443): Max retries exceeded with url: /socket.io/?access_token=97d9d09d13219a0032426fdcf1fe18e656f91a05&agent=pythonquants&wait_for_connection=False&transport=polling&EIO=4&t=1661253054.2434556 (Caused by NewConnectionError('<urllib3.connection.HTTPSConnection object at 0x00000103B46601F0>: Failed to establish a new connection: [Errno 11001] getaddrinfo failed'))
|ERROR|2022-08-23 16:40:59,079|Connection error: HTTPSConnectionPool(host='api-demo.fxcm.com', port=443): Max retries exceeded with url: /socket.io/?access_token=97d9d09d13219a0032426fdcf1fe18e656f91a05&agent=pythonquants&wait_for_connection=False&transport=polling&EIO=4&t=1661253059.0706456 (Caused by NewConnectionError('<urllib3.connection.HTTPSConnection object at 0x00000103B4660B80>: Failed to establish a new connection: [Errno 11001] getaddrinfo failed'))
|ERROR|2022-08-23 16:41:03,674|Connection error: HTTPSConnectionPool(host='api-demo.fxcm.com', port=443): Max retries exceeded with url: /socket.io/?access_token=97d9d09d13219a0032426fdcf1fe18e656f91a05&agent=pythonquants&wait_for_connection=False&transport=polling&EIO=4&t=1661253063.6684113 (Caused by NewConnectionError('<urllib3.connection.HTTPSConnection object at 0x00000103B46604C0>: Failed to establish a new connection: [Errno 11001] getaddrinfo failed'))
|ERROR|2022-08-23 16:41:08,921|Connection error: HTTPSConnectionPool(host='api-demo.fxcm.com', port=443): Max retries exceeded with url: /socket.io/?access_token=97d9d09d13219a0032426fdcf1fe18e656f91a05&agent=pythonquants&wait_for_connection=False&transport=polling&EIO=4&t=1661253068.9011319 (Caused by NewConnectionError('<urllib3.connection.HTTPSConnection object at 0x00000103B4660850>: Failed to establish a new connection: [Errno 11001] getaddrinfo failed'))
|ERROR|2022-08-23 16:41:13,872|Connection error: HTTPSConnectionPool(host='api-demo.fxcm.com', port=443): Max retries exceeded with url: /socket.io/?access_token=97d9d09d13219a0032426fdcf1fe18e656f91a05&agent=pythonquants&wait_for_connection=False&transport=polling&EIO=4&t=1661253073.8655074 (Caused by NewConnectionError('<urllib3.connection.HTTPSConnection object at 0x00000103B46608E0>: Failed to establish a new connection: [Errno 11001] getaddrinfo failed'))
|ERROR|2022-08-23 16:41:18,497|Connection error: HTTPSConnectionPool(host='api-demo.fxcm.com', port=443): Max retries exceeded with url: /socket.io/?access_token=97d9d09d13219a0032426fdcf1fe18e656f91a05&agent=pythonquants&wait_for_connection=False&transport=polling&EIO=4&t=1661253078.4912379 (Caused by NewConnectionError('<urllib3.connection.HTTPSConnection object at 0x00000103B46606A0>: Failed to establish a new connection: [Errno 11001] getaddrinfo failed'))
|ERROR|2022-08-23 16:41:23,792|Connection error: HTTPSConnectionPool(host='api-demo.fxcm.com', port=443): Max retries exceeded with url: /socket.io/?access_token=97d9d09d13219a0032426fdcf1fe18e656f91a05&agent=pythonquants&wait_for_connection=False&transport=polling&EIO=4&t=1661253083.7859514 (Caused by NewConnectionError('<urllib3.connection.HTTPSConnection object at 0x00000103B46608B0>: Failed to establish a new connection: [Errno 11001] getaddrinfo failed'))
|ERROR|2022-08-23 16:41:29,072|Connection error: HTTPSConnectionPool(host='api-demo.fxcm.com', port=443): Max retries exceeded with url: /socket.io/?access_token=97d9d09d13219a0032426fdcf1fe18e656f91a05&agent=pythonquants&wait_for_connection=False&transport=polling&EIO=4&t=1661253089.0659413 (Caused by NewConnectionError('<urllib3.connection.HTTPSConnection object at 0x00000103B4660BE0>: Failed to establish a new connection: [Errno 11001] getaddrinfo failed'))
|ERROR|2022-08-23 16:41:34,384|Connection error: HTTPSConnectionPool(host='api-demo.fxcm.com', port=443): Max retries exceeded with url: /socket.io/?access_token=97d9d09d13219a0032426fdcf1fe18e656f91a05&agent=pythonquants&wait_for_connection=False&transport=polling&EIO=4&t=1661253094.3766837 (Caused by NewConnectionError('<urllib3.connection.HTTPSConnection object at 0x00000103B4660730>: Failed to establish a new connection: [Errno 11001] getaddrinfo failed'))
|ERROR|2022-08-23 16:41:38,952|Connection error: HTTPSConnectionPool(host='api-demo.fxcm.com', port=443): Max retries exceeded with url: /socket.io/?access_token=97d9d09d13219a0032426fdcf1fe18e656f91a05&agent=pythonquants&wait_for_connection=False&transport=polling&EIO=4&t=1661253098.9308267 (Caused by NewConnectionError('<urllib3.connection.HTTPSConnection object at 0x00000103B4660B50>: Failed to establish a new connection: [Errno 11001] getaddrinfo failed'))
|ERROR|2022-08-23 16:41:44,259|Connection error: HTTPSConnectionPool(host='api-demo.fxcm.com', port=443): Max retries exceeded with url: /socket.io/?access_token=97d9d09d13219a0032426fdcf1fe18e656f91a05&agent=pythonquants&wait_for_connection=False&transport=polling&EIO=4&t=1661253104.252936 (Caused by NewConnectionError('<urllib3.connection.HTTPSConnection object at 0x00000103B4660250>: Failed to establish a new connection: [Errno 11001] getaddrinfo failed'))
|ERROR|2022-08-23 16:41:49,147|Connection error: HTTPSConnectionPool(host='api-demo.fxcm.com', port=443): Max retries exceeded with url: /socket.io/?access_token=97d9d09d13219a0032426fdcf1fe18e656f91a05&agent=pythonquants&wait_for_connection=False&transport=polling&EIO=4&t=1661253109.1403096 (Caused by NewConnectionError('<urllib3.connection.HTTPSConnection object at 0x00000103B46605E0>: Failed to establish a new connection: [Errno 11001] getaddrinfo failed'))
|ERROR|2022-08-23 16:41:53,667|Connection error: HTTPSConnectionPool(host='api-demo.fxcm.com', port=443): Max retries exceeded with url: /socket.io/?access_token=97d9d09d13219a0032426fdcf1fe18e656f91a05&agent=pythonquants&wait_for_connection=False&transport=polling&EIO=4&t=1661253113.657696 (Caused by NewConnectionError('<urllib3.connection.HTTPSConnection object at 0x00000103B4660220>: Failed to establish a new connection: [Errno 11001] getaddrinfo failed'))
|ERROR|2022-08-23 16:41:58,469|Connection error: HTTPSConnectionPool(host='api-demo.fxcm.com', port=443): Max retries exceeded with url: /socket.io/?access_token=97d9d09d13219a0032426fdcf1fe18e656f91a05&agent=pythonquants&wait_for_connection=False&transport=polling&EIO=4&t=1661253118.4486692 (Caused by NewConnectionError('<urllib3.connection.HTTPSConnection object at 0x00000103B46602B0>: Failed to establish a new connection: [Errno 11001] getaddrinfo failed'))
|ERROR|2022-08-23 16:42:03,651|Connection error: HTTPSConnectionPool(host='api-demo.fxcm.com', port=443): Max retries exceeded with url: /socket.io/?access_token=97d9d09d13219a0032426fdcf1fe18e656f91a05&agent=pythonquants&wait_for_connection=False&transport=polling&EIO=4&t=1661253123.6228518 (Caused by NewConnectionError('<urllib3.connection.HTTPSConnection object at 0x00000103B4660B80>: Failed to establish a new connection: [Errno 11001] getaddrinfo failed'))
|ERROR|2022-08-23 16:42:09,029|Connection error: HTTPSConnectionPool(host='api-demo.fxcm.com', port=443): Max retries exceeded with url: /socket.io/?access_token=97d9d09d13219a0032426fdcf1fe18e656f91a05&agent=pythonquants&wait_for_connection=False&transport=polling&EIO=4&t=1661253129.0218232 (Caused by NewConnectionError('<urllib3.connection.HTTPSConnection object at 0x00000103B4660880>: Failed to establish a new connection: [Errno 11001] getaddrinfo failed'))
|ERROR|2022-08-23 16:42:13,812|Connection error: HTTPSConnectionPool(host='api-demo.fxcm.com', port=443): Max retries exceeded with url: /socket.io/?access_token=97d9d09d13219a0032426fdcf1fe18e656f91a05&agent=pythonquants&wait_for_connection=False&transport=polling&EIO=4&t=1661253133.805486 (Caused by NewConnectionError('<urllib3.connection.HTTPSConnection object at 0x00000103B4660850>: Failed to establish a new connection: [Errno 11001] getaddrinfo failed'))
|ERROR|2022-08-23 16:42:18,441|Connection error: HTTPSConnectionPool(host='api-demo.fxcm.com', port=443): Max retries exceeded with url: /socket.io/?access_token=97d9d09d13219a0032426fdcf1fe18e656f91a05&agent=pythonquants&wait_for_connection=False&transport=polling&EIO=4&t=1661253138.4345772 (Caused by NewConnectionError('<urllib3.connection.HTTPSConnection object at 0x00000103B4660550>: Failed to establish a new connection: [Errno 11001] getaddrinfo failed'))
|ERROR|2022-08-23 16:42:23,479|Connection error: HTTPSConnectionPool(host='api-demo.fxcm.com', port=443): Max retries exceeded with url: /socket.io/?access_token=97d9d09d13219a0032426fdcf1fe18e656f91a05&agent=pythonquants&wait_for_connection=False&transport=polling&EIO=4&t=1661253143.4598897 (Caused by NewConnectionError('<urllib3.connection.HTTPSConnection object at 0x00000103B46606A0>: Failed to establish a new connection: [Errno 11001] getaddrinfo failed'))
|ERROR|2022-08-23 16:42:28,436|Connection error: HTTPSConnectionPool(host='api-demo.fxcm.com', port=443): Max retries exceeded with url: /socket.io/?access_token=97d9d09d13219a0032426fdcf1fe18e656f91a05&agent=pythonquants&wait_for_connection=False&transport=polling&EIO=4&t=1661253148.4284587 (Caused by NewConnectionError('<urllib3.connection.HTTPSConnection object at 0x00000103B46601F0>: Failed to establish a new connection: [Errno 11001] getaddrinfo failed'))
|ERROR|2022-08-23 16:42:33,377|Connection error: HTTPSConnectionPool(host='api-demo.fxcm.com', port=443): Max retries exceeded with url: /socket.io/?access_token=97d9d09d13219a0032426fdcf1fe18e656f91a05&agent=pythonquants&wait_for_connection=False&transport=polling&EIO=4&t=1661253153.3681672 (Caused by NewConnectionError('<urllib3.connection.HTTPSConnection object at 0x00000103B4660BE0>: Failed to establish a new connection: [Errno 11001] getaddrinfo failed'))
|ERROR|2022-08-23 16:42:38,769|Connection error: HTTPSConnectionPool(host='api-demo.fxcm.com', port=443): Max retries exceeded with url: /socket.io/?access_token=97d9d09d13219a0032426fdcf1fe18e656f91a05&agent=pythonquants&wait_for_connection=False&transport=polling&EIO=4&t=1661253158.7505107 (Caused by NewConnectionError('<urllib3.connection.HTTPSConnection object at 0x00000103B46604C0>: Failed to establish a new connection: [Errno 11001] getaddrinfo failed'))
|ERROR|2022-08-23 16:42:43,401|Connection error: HTTPSConnectionPool(host='api-demo.fxcm.com', port=443): Max retries exceeded with url: /socket.io/?access_token=97d9d09d13219a0032426fdcf1fe18e656f91a05&agent=pythonquants&wait_for_connection=False&transport=polling&EIO=4&t=1661253163.39416 (Caused by NewConnectionError('<urllib3.connection.HTTPSConnection object at 0x00000103B4660B50>: Failed to establish a new connection: [Errno 11001] getaddrinfo failed'))
|ERROR|2022-08-23 16:42:48,403|Connection error: HTTPSConnectionPool(host='api-demo.fxcm.com', port=443): Max retries exceeded with url: /socket.io/?access_token=97d9d09d13219a0032426fdcf1fe18e656f91a05&agent=pythonquants&wait_for_connection=False&transport=polling&EIO=4&t=1661253168.3940504 (Caused by NewConnectionError('<urllib3.connection.HTTPSConnection object at 0x00000103B46608E0>: Failed to establish a new connection: [Errno 11001] getaddrinfo failed'))
|ERROR|2022-08-23 16:42:53,228|Connection error: HTTPSConnectionPool(host='api-demo.fxcm.com', port=443): Max retries exceeded with url: /socket.io/?access_token=97d9d09d13219a0032426fdcf1fe18e656f91a05&agent=pythonquants&wait_for_connection=False&transport=polling&EIO=4&t=1661253173.2096355 (Caused by NewConnectionError('<urllib3.connection.HTTPSConnection object at 0x00000103B46605E0>: Failed to establish a new connection: [Errno 11001] getaddrinfo failed'))
|ERROR|2022-08-23 16:42:57,966|Connection error: HTTPSConnectionPool(host='api-demo.fxcm.com', port=443): Max retries exceeded with url: /socket.io/?access_token=97d9d09d13219a0032426fdcf1fe18e656f91a05&agent=pythonquants&wait_for_connection=False&transport=polling&EIO=4&t=1661253177.9592884 (Caused by NewConnectionError('<urllib3.connection.HTTPSConnection object at 0x00000103B46608B0>: Failed to establish a new connection: [Errno 11001] getaddrinfo failed'))
|ERROR|2022-08-23 16:43:02,982|Connection error: HTTPSConnectionPool(host='api-demo.fxcm.com', port=443): Max retries exceeded with url: /socket.io/?access_token=97d9d09d13219a0032426fdcf1fe18e656f91a05&agent=pythonquants&wait_for_connection=False&transport=polling&EIO=4&t=1661253182.976344 (Caused by NewConnectionError('<urllib3.connection.HTTPSConnection object at 0x00000103B46602B0>: Failed to establish a new connection: [Errno 11001] getaddrinfo failed'))
|ERROR|2022-08-23 16:43:08,490|Connection error: HTTPSConnectionPool(host='api-demo.fxcm.com', port=443): Max retries exceeded with url: /socket.io/?access_token=97d9d09d13219a0032426fdcf1fe18e656f91a05&agent=pythonquants&wait_for_connection=False&transport=polling&EIO=4&t=1661253188.4696999 (Caused by NewConnectionError('<urllib3.connection.HTTPSConnection object at 0x00000103B4660730>: Failed to establish a new connection: [Errno 11001] getaddrinfo failed'))
|ERROR|2022-08-23 16:43:13,649|Connection error: HTTPSConnectionPool(host='api-demo.fxcm.com', port=443): Max retries exceeded with url: /socket.io/?access_token=97d9d09d13219a0032426fdcf1fe18e656f91a05&agent=pythonquants&wait_for_connection=False&transport=polling&EIO=4&t=1661253193.6398008 (Caused by NewConnectionError('<urllib3.connection.HTTPSConnection object at 0x00000103B4660BE0>: Failed to establish a new connection: [Errno 11001] getaddrinfo failed'))
|ERROR|2022-08-23 16:43:18,420|Connection error: HTTPSConnectionPool(host='api-demo.fxcm.com', port=443): Max retries exceeded with url: /socket.io/?access_token=97d9d09d13219a0032426fdcf1fe18e656f91a05&agent=pythonquants&wait_for_connection=False&transport=polling&EIO=4&t=1661253198.4135795 (Caused by NewConnectionError('<urllib3.connection.HTTPSConnection object at 0x00000103B4660250>: Failed to establish a new connection: [Errno 11001] getaddrinfo failed'))
|ERROR|2022-08-23 16:43:23,835|Connection error: HTTPSConnectionPool(host='api-demo.fxcm.com', port=443): Max retries exceeded with url: /socket.io/?access_token=97d9d09d13219a0032426fdcf1fe18e656f91a05&agent=pythonquants&wait_for_connection=False&transport=polling&EIO=4&t=1661253203.8286715 (Caused by NewConnectionError('<urllib3.connection.HTTPSConnection object at 0x00000103B4660220>: Failed to establish a new connection: [Errno 11001] getaddrinfo failed'))
|ERROR|2022-08-23 16:43:28,577|Connection error: HTTPSConnectionPool(host='api-demo.fxcm.com', port=443): Max retries exceeded with url: /socket.io/?access_token=97d9d09d13219a0032426fdcf1fe18e656f91a05&agent=pythonquants&wait_for_connection=False&transport=polling&EIO=4&t=1661253208.5705836 (Caused by NewConnectionError('<urllib3.connection.HTTPSConnection object at 0x00000103B46604C0>: Failed to establish a new connection: [Errno 11001] getaddrinfo failed'))
|ERROR|2022-08-23 16:43:33,606|Connection error: HTTPSConnectionPool(host='api-demo.fxcm.com', port=443): Max retries exceeded with url: /socket.io/?access_token=97d9d09d13219a0032426fdcf1fe18e656f91a05&agent=pythonquants&wait_for_connection=False&transport=polling&EIO=4&t=1661253213.598993 (Caused by NewConnectionError('<urllib3.connection.HTTPSConnection object at 0x00000103B46602E0>: Failed to establish a new connection: [Errno 11001] getaddrinfo failed'))
|ERROR|2022-08-23 16:43:39,011|Connection error: HTTPSConnectionPool(host='api-demo.fxcm.com', port=443): Max retries exceeded with url: /socket.io/?access_token=97d9d09d13219a0032426fdcf1fe18e656f91a05&agent=pythonquants&wait_for_connection=False&transport=polling&EIO=4&t=1661253218.99123 (Caused by NewConnectionError('<urllib3.connection.HTTPSConnection object at 0x00000103B46608E0>: Failed to establish a new connection: [Errno 11001] getaddrinfo failed'))
|ERROR|2022-08-23 16:43:43,994|Connection error: HTTPSConnectionPool(host='api-demo.fxcm.com', port=443): Max retries exceeded with url: /socket.io/?access_token=97d9d09d13219a0032426fdcf1fe18e656f91a05&agent=pythonquants&wait_for_connection=False&transport=polling&EIO=4&t=1661253223.9871435 (Caused by NewConnectionError('<urllib3.connection.HTTPSConnection object at 0x00000103B4660550>: Failed to establish a new connection: [Errno 11001] getaddrinfo failed'))
|ERROR|2022-08-23 16:43:49,252|Connection error: HTTPSConnectionPool(host='api-demo.fxcm.com', port=443): Max retries exceeded with url: /socket.io/?access_token=97d9d09d13219a0032426fdcf1fe18e656f91a05&agent=pythonquants&wait_for_connection=False&transport=polling&EIO=4&t=1661253229.2462807 (Caused by NewConnectionError('<urllib3.connection.HTTPSConnection object at 0x00000103B4660B80>: Failed to establish a new connection: [Errno 11001] getaddrinfo failed'))
|ERROR|2022-08-23 16:43:54,586|Connection error: HTTPSConnectionPool(host='api-demo.fxcm.com', port=443): Max retries exceeded with url: /socket.io/?access_token=97d9d09d13219a0032426fdcf1fe18e656f91a05&agent=pythonquants&wait_for_connection=False&transport=polling&EIO=4&t=1661253234.5657058 (Caused by NewConnectionError('<urllib3.connection.HTTPSConnection object at 0x00000103B46601F0>: Failed to establish a new connection: [Errno 11001] getaddrinfo failed'))
|ERROR|2022-08-23 16:43:59,851|Connection error: HTTPSConnectionPool(host='api-demo.fxcm.com', port=443): Max retries exceeded with url: /socket.io/?access_token=97d9d09d13219a0032426fdcf1fe18e656f91a05&agent=pythonquants&wait_for_connection=False&transport=polling&EIO=4&t=1661253239.8448868 (Caused by NewConnectionError('<urllib3.connection.HTTPSConnection object at 0x00000103B4660850>: Failed to establish a new connection: [Errno 11001] getaddrinfo failed'))
|ERROR|2022-08-23 16:44:05,125|Connection error: HTTPSConnectionPool(host='api-demo.fxcm.com', port=443): Max retries exceeded with url: /socket.io/?access_token=97d9d09d13219a0032426fdcf1fe18e656f91a05&agent=pythonquants&wait_for_connection=False&transport=polling&EIO=4&t=1661253245.1199007 (Caused by NewConnectionError('<urllib3.connection.HTTPSConnection object at 0x00000103B46606A0>: Failed to establish a new connection: [Errno 11001] getaddrinfo failed'))
|ERROR|2022-08-23 16:44:09,717|Connection error: HTTPSConnectionPool(host='api-demo.fxcm.com', port=443): Max retries exceeded with url: /socket.io/?access_token=97d9d09d13219a0032426fdcf1fe18e656f91a05&agent=pythonquants&wait_for_connection=False&transport=polling&EIO=4&t=1661253249.6981218 (Caused by NewConnectionError('<urllib3.connection.HTTPSConnection object at 0x00000103B46605E0>: Failed to establish a new connection: [Errno 11001] getaddrinfo failed'))
|ERROR|2022-08-23 16:44:14,646|Connection error: HTTPSConnectionPool(host='api-demo.fxcm.com', port=443): Max retries exceeded with url: /socket.io/?access_token=97d9d09d13219a0032426fdcf1fe18e656f91a05&agent=pythonquants&wait_for_connection=False&transport=polling&EIO=4&t=1661253254.6336293 (Caused by NewConnectionError('<urllib3.connection.HTTPSConnection object at 0x00000103B46602B0>: Failed to establish a new connection: [Errno 11001] getaddrinfo failed'))
|ERROR|2022-08-23 16:44:19,983|Connection error: HTTPSConnectionPool(host='api-demo.fxcm.com', port=443): Max retries exceeded with url: /socket.io/?access_token=97d9d09d13219a0032426fdcf1fe18e656f91a05&agent=pythonquants&wait_for_connection=False&transport=polling&EIO=4&t=1661253259.9768064 (Caused by NewConnectionError('<urllib3.connection.HTTPSConnection object at 0x00000103B4660970>: Failed to establish a new connection: [Errno 11001] getaddrinfo failed'))
|ERROR|2022-08-23 16:44:24,628|Connection error: HTTPSConnectionPool(host='api-demo.fxcm.com', port=443): Max retries exceeded with url: /socket.io/?access_token=97d9d09d13219a0032426fdcf1fe18e656f91a05&agent=pythonquants&wait_for_connection=False&transport=polling&EIO=4&t=1661253264.621108 (Caused by NewConnectionError('<urllib3.connection.HTTPSConnection object at 0x00000103B4660B50>: Failed to establish a new connection: [Errno 11001] getaddrinfo failed'))
|ERROR|2022-08-23 16:44:29,987|Connection error: HTTPSConnectionPool(host='api-demo.fxcm.com', port=443): Max retries exceeded with url: /socket.io/?access_token=97d9d09d13219a0032426fdcf1fe18e656f91a05&agent=pythonquants&wait_for_connection=False&transport=polling&EIO=4&t=1661253269.9805477 (Caused by NewConnectionError('<urllib3.connection.HTTPSConnection object at 0x00000103B4660BE0>: Failed to establish a new connection: [Errno 11001] getaddrinfo failed'))
|ERROR|2022-08-23 16:44:34,888|Connection error: HTTPSConnectionPool(host='api-demo.fxcm.com', port=443): Max retries exceeded with url: /socket.io/?access_token=97d9d09d13219a0032426fdcf1fe18e656f91a05&agent=pythonquants&wait_for_connection=False&transport=polling&EIO=4&t=1661253274.881212 (Caused by NewConnectionError('<urllib3.connection.HTTPSConnection object at 0x00000103B46608B0>: Failed to establish a new connection: [Errno 11001] getaddrinfo failed'))
|ERROR|2022-08-23 16:44:39,860|Connection error: HTTPSConnectionPool(host='api-demo.fxcm.com', port=443): Max retries exceeded with url: /socket.io/?access_token=97d9d09d13219a0032426fdcf1fe18e656f91a05&agent=pythonquants&wait_for_connection=False&transport=polling&EIO=4&t=1661253279.8473055 (Caused by NewConnectionError('<urllib3.connection.HTTPSConnection object at 0x00000103B4660220>: Failed to establish a new connection: [Errno 11001] getaddrinfo failed'))
|ERROR|2022-08-23 16:44:44,645|Connection error: HTTPSConnectionPool(host='api-demo.fxcm.com', port=443): Max retries exceeded with url: /socket.io/?access_token=97d9d09d13219a0032426fdcf1fe18e656f91a05&agent=pythonquants&wait_for_connection=False&transport=polling&EIO=4&t=1661253284.6416802 (Caused by NewConnectionError('<urllib3.connection.HTTPSConnection object at 0x00000103B4660940>: Failed to establish a new connection: [Errno 11001] getaddrinfo failed'))
|ERROR|2022-08-23 16:44:49,760|Connection error: HTTPSConnectionPool(host='api-demo.fxcm.com', port=443): Max retries exceeded with url: /socket.io/?access_token=97d9d09d13219a0032426fdcf1fe18e656f91a05&agent=pythonquants&wait_for_connection=False&transport=polling&EIO=4&t=1661253289.7535667 (Caused by NewConnectionError('<urllib3.connection.HTTPSConnection object at 0x00000103B46602E0>: Failed to establish a new connection: [Errno 11001] getaddrinfo failed'))
|ERROR|2022-08-23 16:44:55,150|Connection error: HTTPSConnectionPool(host='api-demo.fxcm.com', port=443): Max retries exceeded with url: /socket.io/?access_token=97d9d09d13219a0032426fdcf1fe18e656f91a05&agent=pythonquants&wait_for_connection=False&transport=polling&EIO=4&t=1661253295.1327696 (Caused by NewConnectionError('<urllib3.connection.HTTPSConnection object at 0x00000103B4660250>: Failed to establish a new connection: [Errno 11001] getaddrinfo failed'))
|ERROR|2022-08-23 16:45:00,458|Connection error: HTTPSConnectionPool(host='api-demo.fxcm.com', port=443): Max retries exceeded with url: /socket.io/?access_token=97d9d09d13219a0032426fdcf1fe18e656f91a05&agent=pythonquants&wait_for_connection=False&transport=polling&EIO=4&t=1661253300.4519625 (Caused by NewConnectionError('<urllib3.connection.HTTPSConnection object at 0x00000103B4660550>: Failed to establish a new connection: [Errno 11001] getaddrinfo failed'))
|ERROR|2022-08-23 16:45:05,932|Connection error: HTTPSConnectionPool(host='api-demo.fxcm.com', port=443): Max retries exceeded with url: /socket.io/?access_token=97d9d09d13219a0032426fdcf1fe18e656f91a05&agent=pythonquants&wait_for_connection=False&transport=polling&EIO=4&t=1661253305.926752 (Caused by NewConnectionError('<urllib3.connection.HTTPSConnection object at 0x00000103B46604C0>: Failed to establish a new connection: [Errno 11001] getaddrinfo failed'))
|ERROR|2022-08-23 16:45:11,467|Connection error: HTTPSConnectionPool(host='api-demo.fxcm.com', port=443): Max retries exceeded with url: /socket.io/?access_token=97d9d09d13219a0032426fdcf1fe18e656f91a05&agent=pythonquants&wait_for_connection=False&transport=polling&EIO=4&t=1661253311.4473615 (Caused by NewConnectionError('<urllib3.connection.HTTPSConnection object at 0x00000103B46601F0>: Failed to establish a new connection: [Errno 11001] getaddrinfo failed'))
|ERROR|2022-08-23 16:45:16,227|Connection error: HTTPSConnectionPool(host='api-demo.fxcm.com', port=443): Max retries exceeded with url: /socket.io/?access_token=97d9d09d13219a0032426fdcf1fe18e656f91a05&agent=pythonquants&wait_for_connection=False&transport=polling&EIO=4&t=1661253316.2202048 (Caused by NewConnectionError('<urllib3.connection.HTTPSConnection object at 0x00000103B46608E0>: Failed to establish a new connection: [Errno 11001] getaddrinfo failed'))
|ERROR|2022-08-23 16:45:21,574|Connection error: HTTPSConnectionPool(host='api-demo.fxcm.com', port=443): Max retries exceeded with url: /socket.io/?access_token=97d9d09d13219a0032426fdcf1fe18e656f91a05&agent=pythonquants&wait_for_connection=False&transport=polling&EIO=4&t=1661253321.5682123 (Caused by NewConnectionError('<urllib3.connection.HTTPSConnection object at 0x00000103B46606A0>: Failed to establish a new connection: [Errno 11001] getaddrinfo failed'))
|ERROR|2022-08-23 16:45:26,252|Connection error: HTTPSConnectionPool(host='api-demo.fxcm.com', port=443): Max retries exceeded with url: /socket.io/?access_token=97d9d09d13219a0032426fdcf1fe18e656f91a05&agent=pythonquants&wait_for_connection=False&transport=polling&EIO=4&t=1661253326.2330594 (Caused by NewConnectionError('<urllib3.connection.HTTPSConnection object at 0x00000103B4660B80>: Failed to establish a new connection: [Errno 11001] getaddrinfo failed'))
|ERROR|2022-08-23 16:45:31,458|Connection error: HTTPSConnectionPool(host='api-demo.fxcm.com', port=443): Max retries exceeded with url: /socket.io/?access_token=97d9d09d13219a0032426fdcf1fe18e656f91a05&agent=pythonquants&wait_for_connection=False&transport=polling&EIO=4&t=1661253331.4520655 (Caused by NewConnectionError('<urllib3.connection.HTTPSConnection object at 0x00000103B46602B0>: Failed to establish a new connection: [Errno 11001] getaddrinfo failed'))
|ERROR|2022-08-23 16:45:36,468|Connection error: HTTPSConnectionPool(host='api-demo.fxcm.com', port=443): Max retries exceeded with url: /socket.io/?access_token=97d9d09d13219a0032426fdcf1fe18e656f91a05&agent=pythonquants&wait_for_connection=False&transport=polling&EIO=4&t=1661253336.4614854 (Caused by NewConnectionError('<urllib3.connection.HTTPSConnection object at 0x00000103B4660850>: Failed to establish a new connection: [Errno 11001] getaddrinfo failed'))
|ERROR|2022-08-23 16:45:41,233|Connection error: HTTPSConnectionPool(host='api-demo.fxcm.com', port=443): Max retries exceeded with url: /socket.io/?access_token=97d9d09d13219a0032426fdcf1fe18e656f91a05&agent=pythonquants&wait_for_connection=False&transport=polling&EIO=4&t=1661253341.2150815 (Caused by NewConnectionError('<urllib3.connection.HTTPSConnection object at 0x00000103B4660B50>: Failed to establish a new connection: [Errno 11001] getaddrinfo failed'))
|ERROR|2022-08-23 16:45:46,228|Connection error: HTTPSConnectionPool(host='api-demo.fxcm.com', port=443): Max retries exceeded with url: /socket.io/?access_token=97d9d09d13219a0032426fdcf1fe18e656f91a05&agent=pythonquants&wait_for_connection=False&transport=polling&EIO=4&t=1661253346.22112 (Caused by NewConnectionError('<urllib3.connection.HTTPSConnection object at 0x00000103B46605E0>: Failed to establish a new connection: [Errno 11001] getaddrinfo failed'))
|ERROR|2022-08-23 16:45:50,840|Connection error: HTTPSConnectionPool(host='api-demo.fxcm.com', port=443): Max retries exceeded with url: /socket.io/?access_token=97d9d09d13219a0032426fdcf1fe18e656f91a05&agent=pythonquants&wait_for_connection=False&transport=polling&EIO=4&t=1661253350.833898 (Caused by NewConnectionError('<urllib3.connection.HTTPSConnection object at 0x00000103B46608B0>: Failed to establish a new connection: [Errno 11001] getaddrinfo failed'))
|ERROR|2022-08-23 16:45:55,593|Connection error: HTTPSConnectionPool(host='api-demo.fxcm.com', port=443): Max retries exceeded with url: /socket.io/?access_token=97d9d09d13219a0032426fdcf1fe18e656f91a05&agent=pythonquants&wait_for_connection=False&transport=polling&EIO=4&t=1661253355.586042 (Caused by NewConnectionError('<urllib3.connection.HTTPSConnection object at 0x00000103B4660970>: Failed to establish a new connection: [Errno 11001] getaddrinfo failed'))
|ERROR|2022-08-23 16:46:00,270|Connection error: HTTPSConnectionPool(host='api-demo.fxcm.com', port=443): Max retries exceeded with url: /socket.io/?access_token=97d9d09d13219a0032426fdcf1fe18e656f91a05&agent=pythonquants&wait_for_connection=False&transport=polling&EIO=4&t=1661253360.263555 (Caused by NewConnectionError('<urllib3.connection.HTTPSConnection object at 0x00000103B4660940>: Failed to establish a new connection: [Errno 11001] getaddrinfo failed'))
|ERROR|2022-08-23 16:46:05,620|Connection error: HTTPSConnectionPool(host='api-demo.fxcm.com', port=443): Max retries exceeded with url: /socket.io/?access_token=97d9d09d13219a0032426fdcf1fe18e656f91a05&agent=pythonquants&wait_for_connection=False&transport=polling&EIO=4&t=1661253365.6149006 (Caused by NewConnectionError('<urllib3.connection.HTTPSConnection object at 0x00000103B4660BE0>: Failed to establish a new connection: [Errno 11001] getaddrinfo failed'))
|ERROR|2022-08-23 16:46:10,307|Connection error: HTTPSConnectionPool(host='api-demo.fxcm.com', port=443): Max retries exceeded with url: /socket.io/?access_token=97d9d09d13219a0032426fdcf1fe18e656f91a05&agent=pythonquants&wait_for_connection=False&transport=polling&EIO=4&t=1661253370.3015747 (Caused by NewConnectionError('<urllib3.connection.HTTPSConnection object at 0x00000103B4660250>: Failed to establish a new connection: [Errno 11001] getaddrinfo failed'))
|ERROR|2022-08-23 16:46:15,229|Connection error: HTTPSConnectionPool(host='api-demo.fxcm.com', port=443): Max retries exceeded with url: /socket.io/?access_token=97d9d09d13219a0032426fdcf1fe18e656f91a05&agent=pythonquants&wait_for_connection=False&transport=polling&EIO=4&t=1661253375.222805 (Caused by NewConnectionError('<urllib3.connection.HTTPSConnection object at 0x00000103B4660220>: Failed to establish a new connection: [Errno 11001] getaddrinfo failed'))
|ERROR|2022-08-23 16:46:20,479|Connection error: HTTPSConnectionPool(host='api-demo.fxcm.com', port=443): Max retries exceeded with url: /socket.io/?access_token=97d9d09d13219a0032426fdcf1fe18e656f91a05&agent=pythonquants&wait_for_connection=False&transport=polling&EIO=4&t=1661253380.4708223 (Caused by NewConnectionError('<urllib3.connection.HTTPSConnection object at 0x00000103B46604C0>: Failed to establish a new connection: [Errno 11001] getaddrinfo failed'))
|ERROR|2022-08-23 16:46:25,803|Connection error: HTTPSConnectionPool(host='api-demo.fxcm.com', port=443): Max retries exceeded with url: /socket.io/?access_token=97d9d09d13219a0032426fdcf1fe18e656f91a05&agent=pythonquants&wait_for_connection=False&transport=polling&EIO=4&t=1661253385.7967105 (Caused by NewConnectionError('<urllib3.connection.HTTPSConnection object at 0x00000103B46602E0>: Failed to establish a new connection: [Errno 11001] getaddrinfo failed'))
|ERROR|2022-08-23 16:46:31,270|Connection error: HTTPSConnectionPool(host='api-demo.fxcm.com', port=443): Max retries exceeded with url: /socket.io/?access_token=97d9d09d13219a0032426fdcf1fe18e656f91a05&agent=pythonquants&wait_for_connection=False&transport=polling&EIO=4&t=1661253391.2635782 (Caused by NewConnectionError('<urllib3.connection.HTTPSConnection object at 0x00000103B46608E0>: Failed to establish a new connection: [Errno 11001] getaddrinfo failed'))
|ERROR|2022-08-23 16:46:36,736|Connection error: HTTPSConnectionPool(host='api-demo.fxcm.com', port=443): Max retries exceeded with url: /socket.io/?access_token=97d9d09d13219a0032426fdcf1fe18e656f91a05&agent=pythonquants&wait_for_connection=False&transport=polling&EIO=4&t=1661253396.7298458 (Caused by NewConnectionError('<urllib3.connection.HTTPSConnection object at 0x00000103B4660550>: Failed to establish a new connection: [Errno 11001] getaddrinfo failed'))
|ERROR|2022-08-23 16:46:41,342|Connection error: HTTPSConnectionPool(host='api-demo.fxcm.com', port=443): Max retries exceeded with url: /socket.io/?access_token=97d9d09d13219a0032426fdcf1fe18e656f91a05&agent=pythonquants&wait_for_connection=False&transport=polling&EIO=4&t=1661253401.3359168 (Caused by NewConnectionError('<urllib3.connection.HTTPSConnection object at 0x00000103B4660B80>: Failed to establish a new connection: [Errno 11001] getaddrinfo failed'))
|ERROR|2022-08-23 16:46:46,557|Connection error: HTTPSConnectionPool(host='api-demo.fxcm.com', port=443): Max retries exceeded with url: /socket.io/?access_token=97d9d09d13219a0032426fdcf1fe18e656f91a05&agent=pythonquants&wait_for_connection=False&transport=polling&EIO=4&t=1661253406.5394592 (Caused by NewConnectionError('<urllib3.connection.HTTPSConnection object at 0x00000103B46601F0>: Failed to establish a new connection: [Errno 11001] getaddrinfo failed'))
|ERROR|2022-08-23 16:46:51,874|Connection error: HTTPSConnectionPool(host='api-demo.fxcm.com', port=443): Max retries exceeded with url: /socket.io/?access_token=97d9d09d13219a0032426fdcf1fe18e656f91a05&agent=pythonquants&wait_for_connection=False&transport=polling&EIO=4&t=1661253411.8675416 (Caused by NewConnectionError('<urllib3.connection.HTTPSConnection object at 0x00000103B4660850>: Failed to establish a new connection: [Errno 11001] getaddrinfo failed'))
|ERROR|2022-08-23 16:46:56,793|Connection error: HTTPSConnectionPool(host='api-demo.fxcm.com', port=443): Max retries exceeded with url: /socket.io/?access_token=97d9d09d13219a0032426fdcf1fe18e656f91a05&agent=pythonquants&wait_for_connection=False&transport=polling&EIO=4&t=1661253416.7867649 (Caused by NewConnectionError('<urllib3.connection.HTTPSConnection object at 0x00000103B46606A0>: Failed to establish a new connection: [Errno 11001] getaddrinfo failed'))
|ERROR|2022-08-23 16:47:01,855|Connection error: HTTPSConnectionPool(host='api-demo.fxcm.com', port=443): Max retries exceeded with url: /socket.io/?access_token=97d9d09d13219a0032426fdcf1fe18e656f91a05&agent=pythonquants&wait_for_connection=False&transport=polling&EIO=4&t=1661253421.836121 (Caused by NewConnectionError('<urllib3.connection.HTTPSConnection object at 0x00000103B46605E0>: Failed to establish a new connection: [Errno 11001] getaddrinfo failed'))
|ERROR|2022-08-23 16:47:06,993|Connection error: HTTPSConnectionPool(host='api-demo.fxcm.com', port=443): Max retries exceeded with url: /socket.io/?access_token=97d9d09d13219a0032426fdcf1fe18e656f91a05&agent=pythonquants&wait_for_connection=False&transport=polling&EIO=4&t=1661253426.9866338 (Caused by NewConnectionError('<urllib3.connection.HTTPSConnection object at 0x00000103B46602B0>: Failed to establish a new connection: [Errno 11001] getaddrinfo failed'))
|ERROR|2022-08-23 16:47:11,893|Connection error: HTTPSConnectionPool(host='api-demo.fxcm.com', port=443): Max retries exceeded with url: /socket.io/?access_token=97d9d09d13219a0032426fdcf1fe18e656f91a05&agent=pythonquants&wait_for_connection=False&transport=polling&EIO=4&t=1661253431.8871388 (Caused by NewConnectionError('<urllib3.connection.HTTPSConnection object at 0x00000103B4660970>: Failed to establish a new connection: [Errno 11001] getaddrinfo failed'))
|ERROR|2022-08-23 16:47:16,962|Connection error: HTTPSConnectionPool(host='api-demo.fxcm.com', port=443): Max retries exceeded with url: /socket.io/?access_token=97d9d09d13219a0032426fdcf1fe18e656f91a05&agent=pythonquants&wait_for_connection=False&transport=polling&EIO=4&t=1661253436.9393258 (Caused by NewConnectionError('<urllib3.connection.HTTPSConnection object at 0x00000103B4660B50>: Failed to establish a new connection: [Errno 11001] getaddrinfo failed'))
|ERROR|2022-08-23 16:47:22,141|Connection error: HTTPSConnectionPool(host='api-demo.fxcm.com', port=443): Max retries exceeded with url: /socket.io/?access_token=97d9d09d13219a0032426fdcf1fe18e656f91a05&agent=pythonquants&wait_for_connection=False&transport=polling&EIO=4&t=1661253442.13568 (Caused by NewConnectionError('<urllib3.connection.HTTPSConnection object at 0x00000103B4660BE0>: Failed to establish a new connection: [Errno 11001] getaddrinfo failed'))
|ERROR|2022-08-23 16:47:26,773|Connection error: HTTPSConnectionPool(host='api-demo.fxcm.com', port=443): Max retries exceeded with url: /socket.io/?access_token=97d9d09d13219a0032426fdcf1fe18e656f91a05&agent=pythonquants&wait_for_connection=False&transport=polling&EIO=4&t=1661253446.7598042 (Caused by NewConnectionError('<urllib3.connection.HTTPSConnection object at 0x00000103B46608B0>: Failed to establish a new connection: [Errno 11001] getaddrinfo failed'))
|ERROR|2022-08-23 16:47:31,369|Connection error: HTTPSConnectionPool(host='api-demo.fxcm.com', port=443): Max retries exceeded with url: /socket.io/?access_token=97d9d09d13219a0032426fdcf1fe18e656f91a05&agent=pythonquants&wait_for_connection=False&transport=polling&EIO=4&t=1661253451.363115 (Caused by NewConnectionError('<urllib3.connection.HTTPSConnection object at 0x00000103B4660220>: Failed to establish a new connection: [Errno 11001] getaddrinfo failed'))
|ERROR|2022-08-23 16:47:35,898|Connection error: HTTPSConnectionPool(host='api-demo.fxcm.com', port=443): Max retries exceeded with url: /socket.io/?access_token=97d9d09d13219a0032426fdcf1fe18e656f91a05&agent=pythonquants&wait_for_connection=False&transport=polling&EIO=4&t=1661253455.8774962 (Caused by NewConnectionError('<urllib3.connection.HTTPSConnection object at 0x00000103B4660940>: Failed to establish a new connection: [Errno 11001] getaddrinfo failed'))
|ERROR|2022-08-23 16:47:40,758|Connection error: HTTPSConnectionPool(host='api-demo.fxcm.com', port=443): Max retries exceeded with url: /socket.io/?access_token=97d9d09d13219a0032426fdcf1fe18e656f91a05&agent=pythonquants&wait_for_connection=False&transport=polling&EIO=4&t=1661253460.7470007 (Caused by NewConnectionError('<urllib3.connection.HTTPSConnection object at 0x00000103B46602E0>: Failed to establish a new connection: [Errno 11001] getaddrinfo failed'))
|ERROR|2022-08-23 16:47:45,670|Connection error: HTTPSConnectionPool(host='api-demo.fxcm.com', port=443): Max retries exceeded with url: /socket.io/?access_token=97d9d09d13219a0032426fdcf1fe18e656f91a05&agent=pythonquants&wait_for_connection=False&transport=polling&EIO=4&t=1661253465.6634326 (Caused by NewConnectionError('<urllib3.connection.HTTPSConnection object at 0x00000103B4660250>: Failed to establish a new connection: [Errno 11001] getaddrinfo failed'))
|ERROR|2022-08-23 16:47:51,176|Connection error: HTTPSConnectionPool(host='api-demo.fxcm.com', port=443): Max retries exceeded with url: /socket.io/?access_token=97d9d09d13219a0032426fdcf1fe18e656f91a05&agent=pythonquants&wait_for_connection=False&transport=polling&EIO=4&t=1661253471.1573114 (Caused by NewConnectionError('<urllib3.connection.HTTPSConnection object at 0x00000103B4660550>: Failed to establish a new connection: [Errno 11001] getaddrinfo failed'))
|ERROR|2022-08-23 16:47:56,450|Connection error: HTTPSConnectionPool(host='api-demo.fxcm.com', port=443): Max retries exceeded with url: /socket.io/?access_token=97d9d09d13219a0032426fdcf1fe18e656f91a05&agent=pythonquants&wait_for_connection=False&transport=polling&EIO=4&t=1661253476.4446378 (Caused by NewConnectionError('<urllib3.connection.HTTPSConnection object at 0x00000103B46604C0>: Failed to establish a new connection: [Errno 11001] getaddrinfo failed'))
|ERROR|2022-08-23 16:48:01,678|Connection error: HTTPSConnectionPool(host='api-demo.fxcm.com', port=443): Max retries exceeded with url: /socket.io/?access_token=97d9d09d13219a0032426fdcf1fe18e656f91a05&agent=pythonquants&wait_for_connection=False&transport=polling&EIO=4&t=1661253481.6721454 (Caused by NewConnectionError('<urllib3.connection.HTTPSConnection object at 0x00000103B46601F0>: Failed to establish a new connection: [Errno 11001] getaddrinfo failed'))
|ERROR|2022-08-23 16:48:06,544|Connection error: HTTPSConnectionPool(host='api-demo.fxcm.com', port=443): Max retries exceeded with url: /socket.io/?access_token=97d9d09d13219a0032426fdcf1fe18e656f91a05&agent=pythonquants&wait_for_connection=False&transport=polling&EIO=4&t=1661253486.5271227 (Caused by NewConnectionError('<urllib3.connection.HTTPSConnection object at 0x00000103B46608E0>: Failed to establish a new connection: [Errno 11001] getaddrinfo failed'))
|ERROR|2022-08-23 16:48:11,464|Connection error: HTTPSConnectionPool(host='api-demo.fxcm.com', port=443): Max retries exceeded with url: /socket.io/?access_token=97d9d09d13219a0032426fdcf1fe18e656f91a05&agent=pythonquants&wait_for_connection=False&transport=polling&EIO=4&t=1661253491.457921 (Caused by NewConnectionError('<urllib3.connection.HTTPSConnection object at 0x00000103B46606A0>: Failed to establish a new connection: [Errno 11001] getaddrinfo failed'))
|ERROR|2022-08-23 16:48:16,236|Connection error: HTTPSConnectionPool(host='api-demo.fxcm.com', port=443): Max retries exceeded with url: /socket.io/?access_token=97d9d09d13219a0032426fdcf1fe18e656f91a05&agent=pythonquants&wait_for_connection=False&transport=polling&EIO=4&t=1661253496.2306852 (Caused by NewConnectionError('<urllib3.connection.HTTPSConnection object at 0x00000103B4660B80>: Failed to establish a new connection: [Errno 11001] getaddrinfo failed'))
|ERROR|2022-08-23 16:48:20,929|Connection error: HTTPSConnectionPool(host='api-demo.fxcm.com', port=443): Max retries exceeded with url: /socket.io/?access_token=97d9d09d13219a0032426fdcf1fe18e656f91a05&agent=pythonquants&wait_for_connection=False&transport=polling&EIO=4&t=1661253500.9084878 (Caused by NewConnectionError('<urllib3.connection.HTTPSConnection object at 0x00000103B46602B0>: Failed to establish a new connection: [Errno 11001] getaddrinfo failed'))
|ERROR|2022-08-23 16:48:25,982|Connection error: HTTPSConnectionPool(host='api-demo.fxcm.com', port=443): Max retries exceeded with url: /socket.io/?access_token=97d9d09d13219a0032426fdcf1fe18e656f91a05&agent=pythonquants&wait_for_connection=False&transport=polling&EIO=4&t=1661253505.9768355 (Caused by NewConnectionError('<urllib3.connection.HTTPSConnection object at 0x00000103B4660850>: Failed to establish a new connection: [Errno 11001] getaddrinfo failed'))
|ERROR|2022-08-23 16:48:31,168|Connection error: HTTPSConnectionPool(host='api-demo.fxcm.com', port=443): Max retries exceeded with url: /socket.io/?access_token=97d9d09d13219a0032426fdcf1fe18e656f91a05&agent=pythonquants&wait_for_connection=False&transport=polling&EIO=4&t=1661253511.1611156 (Caused by NewConnectionError('<urllib3.connection.HTTPSConnection object at 0x00000103B4660B50>: Failed to establish a new connection: [Errno 11001] getaddrinfo failed'))
|ERROR|2022-08-23 16:48:36,129|Connection error: HTTPSConnectionPool(host='api-demo.fxcm.com', port=443): Max retries exceeded with url: /socket.io/?access_token=97d9d09d13219a0032426fdcf1fe18e656f91a05&agent=pythonquants&wait_for_connection=False&transport=polling&EIO=4&t=1661253516.1108868 (Caused by NewConnectionError('<urllib3.connection.HTTPSConnection object at 0x00000103B46605E0>: Failed to establish a new connection: [Errno 11001] getaddrinfo failed'))
|ERROR|2022-08-23 16:48:40,705|Connection error: HTTPSConnectionPool(host='api-demo.fxcm.com', port=443): Max retries exceeded with url: /socket.io/?access_token=97d9d09d13219a0032426fdcf1fe18e656f91a05&agent=pythonquants&wait_for_connection=False&transport=polling&EIO=4&t=1661253520.6983905 (Caused by NewConnectionError('<urllib3.connection.HTTPSConnection object at 0x00000103B46608B0>: Failed to establish a new connection: [Errno 11001] getaddrinfo failed'))
|ERROR|2022-08-23 16:48:45,333|Connection error: HTTPSConnectionPool(host='api-demo.fxcm.com', port=443): Max retries exceeded with url: /socket.io/?access_token=97d9d09d13219a0032426fdcf1fe18e656f91a05&agent=pythonquants&wait_for_connection=False&transport=polling&EIO=4&t=1661253525.3301663 (Caused by NewConnectionError('<urllib3.connection.HTTPSConnection object at 0x00000103B4660970>: Failed to establish a new connection: [Errno 11001] getaddrinfo failed'))
|ERROR|2022-08-23 16:48:49,983|Connection error: HTTPSConnectionPool(host='api-demo.fxcm.com', port=443): Max retries exceeded with url: /socket.io/?access_token=97d9d09d13219a0032426fdcf1fe18e656f91a05&agent=pythonquants&wait_for_connection=False&transport=polling&EIO=4&t=1661253529.976811 (Caused by NewConnectionError('<urllib3.connection.HTTPSConnection object at 0x00000103B4660940>: Failed to establish a new connection: [Errno 11001] getaddrinfo failed'))
|ERROR|2022-08-23 16:48:55,296|Connection error: HTTPSConnectionPool(host='api-demo.fxcm.com', port=443): Max retries exceeded with url: /socket.io/?access_token=97d9d09d13219a0032426fdcf1fe18e656f91a05&agent=pythonquants&wait_for_connection=False&transport=polling&EIO=4&t=1661253535.2905998 (Caused by NewConnectionError('<urllib3.connection.HTTPSConnection object at 0x00000103B46602B0>: Failed to establish a new connection: [Errno 11001] getaddrinfo failed'))
|ERROR|2022-08-23 16:49:00,141|Connection error: HTTPSConnectionPool(host='api-demo.fxcm.com', port=443): Max retries exceeded with url: /socket.io/?access_token=97d9d09d13219a0032426fdcf1fe18e656f91a05&agent=pythonquants&wait_for_connection=False&transport=polling&EIO=4&t=1661253540.1357336 (Caused by NewConnectionError('<urllib3.connection.HTTPSConnection object at 0x00000103B4660250>: Failed to establish a new connection: [Errno 11001] getaddrinfo failed'))
|ERROR|2022-08-23 16:49:05,219|Connection error: HTTPSConnectionPool(host='api-demo.fxcm.com', port=443): Max retries exceeded with url: /socket.io/?access_token=97d9d09d13219a0032426fdcf1fe18e656f91a05&agent=pythonquants&wait_for_connection=False&transport=polling&EIO=4&t=1661253545.2132776 (Caused by NewConnectionError('<urllib3.connection.HTTPSConnection object at 0x00000103B4660220>: Failed to establish a new connection: [Errno 11001] getaddrinfo failed'))
|ERROR|2022-08-23 16:49:10,089|Connection error: HTTPSConnectionPool(host='api-demo.fxcm.com', port=443): Max retries exceeded with url: /socket.io/?access_token=97d9d09d13219a0032426fdcf1fe18e656f91a05&agent=pythonquants&wait_for_connection=False&transport=polling&EIO=4&t=1661253550.0698483 (Caused by NewConnectionError('<urllib3.connection.HTTPSConnection object at 0x00000103B46604C0>: Failed to establish a new connection: [Errno 11001] getaddrinfo failed'))
|ERROR|2022-08-23 16:49:15,300|Connection error: HTTPSConnectionPool(host='api-demo.fxcm.com', port=443): Max retries exceeded with url: /socket.io/?access_token=97d9d09d13219a0032426fdcf1fe18e656f91a05&agent=pythonquants&wait_for_connection=False&transport=polling&EIO=4&t=1661253555.2939136 (Caused by NewConnectionError('<urllib3.connection.HTTPSConnection object at 0x00000103B4660880>: Failed to establish a new connection: [Errno 11001] getaddrinfo failed'))
|ERROR|2022-08-23 16:49:20,327|Connection error: HTTPSConnectionPool(host='api-demo.fxcm.com', port=443): Max retries exceeded with url: /socket.io/?access_token=97d9d09d13219a0032426fdcf1fe18e656f91a05&agent=pythonquants&wait_for_connection=False&transport=polling&EIO=4&t=1661253560.3212807 (Caused by NewConnectionError('<urllib3.connection.HTTPSConnection object at 0x00000103B46608E0>: Failed to establish a new connection: [Errno 11001] getaddrinfo failed'))
|ERROR|2022-08-23 16:49:25,802|Connection error: HTTPSConnectionPool(host='api-demo.fxcm.com', port=443): Max retries exceeded with url: /socket.io/?access_token=97d9d09d13219a0032426fdcf1fe18e656f91a05&agent=pythonquants&wait_for_connection=False&transport=polling&EIO=4&t=1661253565.782975 (Caused by NewConnectionError('<urllib3.connection.HTTPSConnection object at 0x00000103B4660550>: Failed to establish a new connection: [Errno 11001] getaddrinfo failed'))
|ERROR|2022-08-23 16:49:30,876|Connection error: HTTPSConnectionPool(host='api-demo.fxcm.com', port=443): Max retries exceeded with url: /socket.io/?access_token=97d9d09d13219a0032426fdcf1fe18e656f91a05&agent=pythonquants&wait_for_connection=False&transport=polling&EIO=4&t=1661253570.8702817 (Caused by NewConnectionError('<urllib3.connection.HTTPSConnection object at 0x00000103B46602E0>: Failed to establish a new connection: [Errno 11001] getaddrinfo failed'))
|ERROR|2022-08-23 16:49:35,512|Connection error: HTTPSConnectionPool(host='api-demo.fxcm.com', port=443): Max retries exceeded with url: /socket.io/?access_token=97d9d09d13219a0032426fdcf1fe18e656f91a05&agent=pythonquants&wait_for_connection=False&transport=polling&EIO=4&t=1661253575.5059505 (Caused by NewConnectionError('<urllib3.connection.HTTPSConnection object at 0x00000103B46601F0>: Failed to establish a new connection: [Errno 11001] getaddrinfo failed'))
|ERROR|2022-08-23 16:49:40,168|Connection error: HTTPSConnectionPool(host='api-demo.fxcm.com', port=443): Max retries exceeded with url: /socket.io/?access_token=97d9d09d13219a0032426fdcf1fe18e656f91a05&agent=pythonquants&wait_for_connection=False&transport=polling&EIO=4&t=1661253580.160669 (Caused by NewConnectionError('<urllib3.connection.HTTPSConnection object at 0x00000103B4660850>: Failed to establish a new connection: [Errno 11001] getaddrinfo failed'))
|ERROR|2022-08-23 19:06:58,797|Connection error: HTTPSConnectionPool(host='api-demo.fxcm.com', port=443): Max retries exceeded with url: /socket.io/?access_token=97d9d09d13219a0032426fdcf1fe18e656f91a05&agent=pythonquants&wait_for_connection=False&transport=polling&EIO=4&t=1661261818.7649891 (Caused by NewConnectionError('<urllib3.connection.HTTPSConnection object at 0x00000103B46606A0>: Failed to establish a new connection: [Errno 11001] getaddrinfo failed'))
|ERROR|2022-08-23 19:07:03,794|Connection error: HTTPSConnectionPool(host='api-demo.fxcm.com', port=443): Max retries exceeded with url: /socket.io/?access_token=97d9d09d13219a0032426fdcf1fe18e656f91a05&agent=pythonquants&wait_for_connection=False&transport=polling&EIO=4&t=1661261823.7926128 (Caused by NewConnectionError('<urllib3.connection.HTTPSConnection object at 0x00000103B46605E0>: Failed to establish a new connection: [Errno 11001] getaddrinfo failed'))
|ERROR|2022-08-23 20:46:14,920|Connection error: HTTPSConnectionPool(host='api-demo.fxcm.com', port=443): Max retries exceeded with url: /socket.io/?access_token=97d9d09d13219a0032426fdcf1fe18e656f91a05&agent=pythonquants&wait_for_connection=False&transport=polling&EIO=4&t=1661267774.9075165 (Caused by NewConnectionError('<urllib3.connection.HTTPSConnection object at 0x00000103B4660970>: Failed to establish a new connection: [Errno 11001] getaddrinfo failed'))
|ERROR|2022-08-24 00:01:37,782|Connection error: HTTPSConnectionPool(host='api-demo.fxcm.com', port=443): Read timed out. (read timeout=5)
